{
    "registryname": "ivaddition_sky_of_fantasy",
    "localizedname":"奇迹顶点",
    "color": "FF33FF",
    "modifiers":[
        {
            "x": 7,
            "y": -2,
            "z": 2,
            "elements": [
                "blockbooster:booster_t2"
            ],
            "description":"减少75%的处理时间，降低50%能耗,提升50%能源输出",
            "modifier":[
                {
                    "target": "modularmachinery:energy",
                    "io": "output",
                    "operation": 1,
                    "multiplier": 1.5
                },
                {
                "target": "modularmachinery:energy",
                "io": "input",
                "operation": 1,
                "multiplier": 0.5
                },
                {
                "target": "modularmachinery:duration",
                "io": "input",
                "operation": 1,
                "multiplier": 0.25
                }
            ]
        },
        {
            "x": 7,
            "y": -2,
            "z": 4,
            "elements": [
                "blockbooster:booster_t2"
            ],
            "description":"减少75%的处理时间，降低50%能耗,提升50%能源输出",
            "modifier":[
                {
                    "target": "modularmachinery:energy",
                    "io": "output",
                    "operation": 1,
                    "multiplier": 1.5
                },
                {
                "target": "modularmachinery:energy",
                "io": "input",
                "operation": 1,
                "multiplier": 0.5
                },
                {
                "target": "modularmachinery:duration",
                "io": "input",
                "operation": 1,
                "multiplier": 0.25
                }
            ]
        },
        {
            "x": 1,
            "y": -2,
            "z": 10,
            "elements": [
                "blockbooster:booster_t2"
            ],
            "description":"减少75%的处理时间，降低50%能耗,提升50%能源输出",
            "modifier":[
                {
                    "target": "modularmachinery:energy",
                    "io": "output",
                    "operation": 1,
                    "multiplier": 1.5
                },
                {
                "target": "modularmachinery:energy",
                "io": "input",
                "operation": 1,
                "multiplier": 0.5
                },
                {
                "target": "modularmachinery:duration",
                "io": "input",
                "operation": 1,
                "multiplier": 0.25
                }
            ]
        },        
        {
            "x": -7,
            "y": -2,
            "z": 2,
            "elements": [
                "blockbooster:booster_t2"
            ],
            "description":"减少75%的处理时间，降低50%能耗,提升50%能源输出",
            "modifier":[
                {
                    "target": "modularmachinery:energy",
                    "io": "output",
                    "operation": 1,
                    "multiplier": 1.5
                },
                {
                "target": "modularmachinery:energy",
                "io": "input",
                "operation": 1,
                "multiplier": 0.5
                },
                {
                "target": "modularmachinery:duration",
                "io": "input",
                "operation": 1,
                "multiplier": 0.25
                }
            ]
        },
        {
            "x": 1,
            "y": -2,
            "z": -3,
            "elements": [
                "blockbooster:booster_t2"
            ],
            "description":"减少75%的处理时间，降低50%能耗,提升50%能源输出",
            "modifier":[
                {
                    "target": "modularmachinery:energy",
                    "io": "output",
                    "operation": 1,
                    "multiplier": 1.5
                },
                {
                "target": "modularmachinery:energy",
                "io": "input",
                "operation": 1,
                "multiplier": 0.5
                },
                {
                "target": "modularmachinery:duration",
                "io": "input",
                "operation": 1,
                "multiplier": 0.25
                }
            ]
        },
        {
            "x": -1,
            "y": -2,
            "z": 10,
            "elements": [
                "blockbooster:booster_t2"
            ],
            "description":"减少75%的处理时间，降低50%能耗,提升50%能源输出",
            "modifier":[
                {
                    "target": "modularmachinery:energy",
                    "io": "output",
                    "operation": 1,
                    "multiplier": 1.5
                },
                {
                "target": "modularmachinery:energy",
                "io": "input",
                "operation": 1,
                "multiplier": 0.5
                },
                {
                "target": "modularmachinery:duration",
                "io": "input",
                "operation": 1,
                "multiplier": 0.25
                }
            ]
        },
        {
            "x": -1,
            "y": -2,
            "z": -3,
            "elements": [
                "blockbooster:booster_t2"
            ],
            "description":"减少75%的处理时间，降低50%能耗,提升50%能源输出",
            "modifier":[
                {
                    "target": "modularmachinery:energy",
                    "io": "output",
                    "operation": 1,
                    "multiplier": 1.5
                },
                {
                "target": "modularmachinery:energy",
                "io": "input",
                "operation": 1,
                "multiplier": 0.5
                },
                {
                "target": "modularmachinery:duration",
                "io": "input",
                "operation": 1,
                "multiplier": 0.25
                }
            ]
        },        
        {
            "x": -7,
            "y": -2,
            "z": 4,
            "elements": [
                "blockbooster:booster_t2"
            ],
            "description":"减少75%的处理时间，降低50%能耗,提升50%能源输出",
            "modifier":[
                {
                    "target": "modularmachinery:energy",
                    "io": "output",
                    "operation": 1,
                    "multiplier": 1.5
                },
                {
                "target": "modularmachinery:energy",
                "io": "input",
                "operation": 1,
                "multiplier": 0.5
                },
                {
                "target": "modularmachinery:duration",
                "io": "input",
                "operation": 1,
                "multiplier": 0.25
                }
            ]
        },
        {
            "x": 7,
            "y": -2,
            "z": 2,
            "elements": [
                "blockbooster:booster_t1"
            ],
            "description":"减少25%的处理时间，降低25%能耗,提升25%能源输出",
            "modifier":[
                {
                    "target": "modularmachinery:energy",
                    "io": "output",
                    "operation": 1,
                    "multiplier": 1.25
                },
                {
                "target": "modularmachinery:energy",
                "io": "input",
                "operation": 1,
                "multiplier": 0.75
                },
                {
                "target": "modularmachinery:duration",
                "io": "input",
                "operation": 1,
                "multiplier": 0.75
                }
            ]
        },
        {
            "x": 7,
            "y": -2,
            "z": 4,
            "elements": [
                "blockbooster:booster_t1"
            ],
            "description":"减少25%的处理时间，降低25%能耗,提升25%能源输出",
            "modifier":[
                {
                    "target": "modularmachinery:energy",
                    "io": "output",
                    "operation": 1,
                    "multiplier": 1.25
                },
                {
                "target": "modularmachinery:energy",
                "io": "input",
                "operation": 1,
                "multiplier": 0.75
                },
                {
                "target": "modularmachinery:duration",
                "io": "input",
                "operation": 1,
                "multiplier": 0.75
                }
            ]
        },
        {
            "x": 1,
            "y": -2,
            "z": 10,
            "elements": [
                "blockbooster:booster_t1"
            ],
            "description":"减少25%的处理时间，降低25%能耗,提升25%能源输出",
            "modifier":[
                {
                    "target": "modularmachinery:energy",
                    "io": "output",
                    "operation": 1,
                    "multiplier": 1.25
                },
                {
                "target": "modularmachinery:energy",
                "io": "input",
                "operation": 1,
                "multiplier": 0.75
                },
                {
                "target": "modularmachinery:duration",
                "io": "input",
                "operation": 1,
                "multiplier": 0.75
                }
            ]
        },        
        {
            "x": -7,
            "y": -2,
            "z": 2,
            "elements": [
                "blockbooster:booster_t1"
            ],
            "description":"减少25%的处理时间，降低25%能耗,提升25%能源输出",
            "modifier":[
                {
                    "target": "modularmachinery:energy",
                    "io": "output",
                    "operation": 1,
                    "multiplier": 1.25
                },
                {
                "target": "modularmachinery:energy",
                "io": "input",
                "operation": 1,
                "multiplier": 0.75
                },
                {
                "target": "modularmachinery:duration",
                "io": "input",
                "operation": 1,
                "multiplier": 0.75
                }
            ]
        },
        {
            "x": 1,
            "y": -2,
            "z": -3,
            "elements": [
                "blockbooster:booster_t1"
            ],
            "description":"减少25%的处理时间，降低25%能耗,提升25%能源输出",
            "modifier":[
                {
                    "target": "modularmachinery:energy",
                    "io": "output",
                    "operation": 1,
                    "multiplier": 1.25
                },
                {
                "target": "modularmachinery:energy",
                "io": "input",
                "operation": 1,
                "multiplier": 0.75
                },
                {
                "target": "modularmachinery:duration",
                "io": "input",
                "operation": 1,
                "multiplier": 0.75
                }
            ]
        },
        {
            "x": -1,
            "y": -2,
            "z": 10,
            "elements": [
                "blockbooster:booster_t1"
            ],
            "description":"减少25%的处理时间，降低25%能耗,提升25%能源输出",
            "modifier":[
                {
                    "target": "modularmachinery:energy",
                    "io": "output",
                    "operation": 1,
                    "multiplier": 1.25
                },
                {
                "target": "modularmachinery:energy",
                "io": "input",
                "operation": 1,
                "multiplier": 0.75
                },
                {
                "target": "modularmachinery:duration",
                "io": "input",
                "operation": 1,
                "multiplier": 0.75
                }
            ]
        },
        {
            "x": -1,
            "y": -2,
            "z": -3,
            "elements": [
                "blockbooster:booster_t1"
            ],
            "description":"减少25%的处理时间，降低25%能耗,提升25%能源输出",
            "modifier":[
                {
                    "target": "modularmachinery:energy",
                    "io": "output",
                    "operation": 1,
                    "multiplier": 1.25
                },
                {
                "target": "modularmachinery:energy",
                "io": "input",
                "operation": 1,
                "multiplier": 0.75
                },
                {
                "target": "modularmachinery:duration",
                "io": "input",
                "operation": 1,
                "multiplier": 0.75
                }
            ]
        },        
        {
            "x": -7,
            "y": -2,
            "z": 4,
            "elements": [
                "blockbooster:booster_t1"
            ],
            "description":"减少25%的处理时间，降低25%能耗,提升25%能源输出",
            "modifier":[
                {
                    "target": "modularmachinery:energy",
                    "io": "output",
                    "operation": 1,
                    "multiplier": 1.25
                },
                {
                "target": "modularmachinery:energy",
                "io": "input",
                "operation": 1,
                "multiplier": 0.75
                },
                {
                "target": "modularmachinery:duration",
                "io": "input",
                "operation": 1,
                "multiplier": 0.75
                }
            ]
        }
    ],
    "parts": [
        {
            "x": 1,
            "y": -5,
            "z": 7,
            "elements": [
                "chisel:futura@4"
            ]
        },
        {
            "x": 1,
            "y": -5,
            "z": 8,
            "elements": [
                "actuallyadditions:block_crystal_empowered@0"
            ]
        },
        {
            "x": 1,
            "y": -5,
            "z": 9,
            "elements": [
                "chisel:futura@4"
            ]
        },
        {
            "x": 1,
            "y": -5,
            "z": 10,
            "elements": [
                "actuallyadditions:block_crystal_empowered@1"
            ]
        },
        {
            "x": 1,
            "y": -5,
            "z": 3,
            "elements": [
                "chisel:futura@4"
            ]
        },
        {
            "x": 1,
            "y": -5,
            "z": 4,
            "elements": [
                "chisel:futura@4"
            ]
        },
        {
            "x": 1,
            "y": -5,
            "z": 5,
            "elements": [
                "astraladditions:block_starmetal@0"
            ]
        },
        {
            "x": 1,
            "y": -5,
            "z": 6,
            "elements": [
                "chisel:futura@4"
            ]
        },
        {
            "x": 1,
            "y": -5,
            "z": -1,
            "elements": [
                "chisel:futura@4"
            ]
        },
        {
            "x": 1,
            "y": -5,
            "z": 0,
            "elements": [
                "chisel:futura@4"
            ]
        },
        {
            "x": 1,
            "y": -5,
            "z": 1,
            "elements": [
                "astraladditions:block_starmetal@0"
            ]
        },
        {
            "x": 1,
            "y": -5,
            "z": 2,
            "elements": [
                "chisel:futura@4"
            ]
        },
        {
            "x": 1,
            "y": -5,
            "z": -5,
            "elements": [
                "chisel:futura@4"
            ]
        },
        {
            "x": 1,
            "y": -5,
            "z": -4,
            "elements": [
                "actuallyadditions:block_crystal_empowered@1"
            ]
        },
        {
            "x": 1,
            "y": -5,
            "z": -3,
            "elements": [
                "chisel:futura@4"
            ]
        },
        {
            "x": 1,
            "y": -5,
            "z": -2,
            "elements": [
                "actuallyadditions:block_crystal_empowered@0"
            ]
        },
        {
            "x": 1,
            "y": -5,
            "z": -9,
            "elements": [
                "chisel:futura@4"
            ]
        },
        {
            "x": 1,
            "y": -5,
            "z": -8,
            "elements": [
                "actuallyadditions:block_crystal_empowered@3"
            ]
        },
        {
            "x": 1,
            "y": -5,
            "z": -7,
            "elements": [
                "chisel:futura@4"
            ]
        },
        {
            "x": 1,
            "y": -5,
            "z": -6,
            "elements": [
                "actuallyadditions:block_crystal_empowered@2"
            ]
        },
        {
            "x": 1,
            "y": -5,
            "z": -13,
            "elements": [
                "chisel:futura@4"
            ]
        },
        {
            "x": 1,
            "y": -5,
            "z": -12,
            "elements": [
                "chisel:futura@2"
            ]
        },
        {
            "x": 1,
            "y": -5,
            "z": -11,
            "elements": [
                "chisel:futura@4"
            ]
        },
        {
            "x": 1,
            "y": -5,
            "z": -10,
            "elements": [
                "actuallyadditions:block_crystal_empowered@4"
            ]
        },
        {
            "x": 1,
            "y": -5,
            "z": -14,

            "elements": [
                "modularmachinery:blockcasing@4"
            ]
        },
        {
            "x": 3,
            "y": -3,
            "z": 22,
            "elements": [
                "extendedcrafting:storage@1"
            ]
        },
        {
            "x": 3,
            "y": -3,
            "z": 21,
            "elements": [
                "minecraft:sea_lantern@0"
            ]
        },
        {
            "x": 3,
            "y": -3,
            "z": 20,

            "elements": [
                "modularmachinery:blockcasing@4"
            ]
        },
        {
            "x": 3,
            "y": -3,
            "z": 19,
            "elements": [
                "minecraft:sea_lantern@0"
            ]
        },
        {
            "x": 3,
            "y": -3,
            "z": 18,
            "elements": [
                "extendedcrafting:storage@0"
            ]
        },
        {
            "x": -16,
            "y": 1,
            "z": -4,

            "elements": [
                "modularmachinery:blockcasing@4"
            ]
        },
        {
            "x": -16,
            "y": 1,
            "z": -3,

            "elements": [
                "modularmachinery:blockcasing@4"
            ]
        },
        {
            "x": 1,
            "y": -5,
            "z": 19,
            "elements": [
                "chisel:futura@4"
            ]
        },
        {
            "x": 1,
            "y": -5,
            "z": 20,

            "elements": [
                "modularmachinery:blockcasing@4"
            ]
        },
        {
            "x": 1,
            "y": -5,
            "z": 15,
            "elements": [
                "chisel:futura@4"
            ]
        },
        {
            "x": 1,
            "y": -5,
            "z": 16,
            "elements": [
                "actuallyadditions:block_crystal_empowered@4"
            ]
        },
        {
            "x": 1,
            "y": -5,
            "z": 17,
            "elements": [
                "chisel:futura@4"
            ]
        },
        {
            "x": 1,
            "y": -5,
            "z": 18,
            "elements": [
                "chisel:futura@2"
            ]
        },
        {
            "x": 1,
            "y": -5,
            "z": 11,
            "elements": [
                "chisel:futura@4"
            ]
        },
        {
            "x": 1,
            "y": -5,
            "z": 12,
            "elements": [
                "actuallyadditions:block_crystal_empowered@2"
            ]
        },
        {
            "x": 1,
            "y": -5,
            "z": 13,
            "elements": [
                "chisel:futura@4"
            ]
        },
        {
            "x": 1,
            "y": -5,
            "z": 14,
            "elements": [
                "actuallyadditions:block_crystal_empowered@3"
            ]
        },
        {
            "x": 5,
            "y": -1,
            "z": 21,
            "elements": [
                "extendedcrafting:storage@1"
            ]
        },
        {
            "x": 5,
            "y": -1,
            "z": 19,

            "elements": [
                "modularmachinery:blockcasing@4"
            ]
        },
        {
            "x": 5,
            "y": -1,
            "z": 20,
            "elements": [
                "minecraft:sea_lantern@0"
            ]
        },
        {
            "x": 4,
            "y": 0,
            "z": -15,
            "elements": [
                "minecraft:sea_lantern@0"
            ]
        },
        {
            "x": 4,
            "y": 0,
            "z": -14,

            "elements": [
                "modularmachinery:blockcasing@4"
            ]
        },
        {
            "x": -17,
            "y": -2,
            "z": 3,

            "elements": [
                "modularmachinery:blockcasing@4"
            ]
        },
        {
            "x": -17,
            "y": -2,
            "z": 2,

            "elements": [
                "modularmachinery:blockcasing@4"
            ]
        },
        {
            "x": -17,
            "y": -2,
            "z": 5,

            "elements": [
                "modularmachinery:blockcasing@4"
            ]
        },
        {
            "x": -17,
            "y": -2,
            "z": 4,

            "elements": [
                "modularmachinery:blockcasing@4"
            ]
        },
        {
            "x": 4,
            "y": 0,
            "z": -13,
            "elements": [
                "minecraft:sea_lantern@0"
            ]
        },
        {
            "x": -17,
            "y": -2,
            "z": 7,

            "elements": [
                "modularmachinery:blockcasing@4"
            ]
        },
        {
            "x": 4,
            "y": 0,
            "z": -12,
            "elements": [
                "minecraft:sea_lantern@0"
            ]
        },
        {
            "x": -17,
            "y": -2,
            "z": 6,

            "elements": [
                "modularmachinery:blockcasing@4"
            ]
        },
        {
            "x": -17,
            "y": -2,
            "z": 9,
            "elements": [
                "minecraft:sea_lantern@0"
            ]
        },
        {
            "x": -17,
            "y": -2,
            "z": 8,
            "elements": [
                "minecraft:sea_lantern@0"
            ]
        },
        {
            "x": -18,
            "y": -1,
            "z": -3,
            "elements": [
                "extendedcrafting:storage@1"
            ]
        },
        {
            "x": -17,
            "y": -2,
            "z": 11,
            "elements": [
                "extendedcrafting:storage@1"
            ]
        },
        {
            "x": -18,
            "y": -1,
            "z": -4,
            "elements": [
                "extendedcrafting:storage@1"
            ]
        },
        {
            "x": -17,
            "y": -2,
            "z": 10,
            "elements": [
                "minecraft:sea_lantern@0"
            ]
        },
        {
            "x": -17,
            "y": -2,
            "z": 13,
            "elements": [
                "extendedcrafting:storage@2"
            ]
        },
        {
            "x": -17,
            "y": -2,
            "z": 12,
            "elements": [
                "extendedcrafting:storage@1"
            ]
        },
        {
            "x": -18,
            "y": -1,
            "z": 1,
            "elements": [
                "minecraft:sea_lantern@0"
            ]
        },
        {
            "x": 5,
            "y": -1,
            "z": 17,
            "elements": [
                "extendedcrafting:storage@0"
            ]
        },
        {
            "x": -18,
            "y": -1,
            "z": 0,
            "elements": [
                "minecraft:sea_lantern@0"
            ]
        },
        {
            "x": -17,
            "y": -2,
            "z": 14,
            "elements": [
                "extendedcrafting:storage@2"
            ]
        },
        {
            "x": 5,
            "y": -1,
            "z": 18,
            "elements": [
                "minecraft:sea_lantern@0"
            ]
        },
        {
            "x": -18,
            "y": -1,
            "z": -1,
            "elements": [
                "minecraft:sea_lantern@0"
            ]
        },
        {
            "x": -18,
            "y": -1,
            "z": -2,
            "elements": [
                "extendedcrafting:storage@1"
            ]
        },
        {
            "x": 5,
            "y": -1,
            "z": -11,
            "elements": [
                "extendedcrafting:storage@0"
            ]
        },
        {
            "x": -18,
            "y": -1,
            "z": 5,
            "elements": [
                "minecraft:sea_lantern@0"
            ]
        },
        {
            "x": -18,
            "y": -1,
            "z": 4,
            "elements": [
                "minecraft:sea_lantern@0"
            ]
        },
        {
            "x": 5,
            "y": -1,
            "z": -13,

            "elements": [
                "modularmachinery:blockcasing@4"
            ]
        },
        {
            "x": -18,
            "y": -1,
            "z": 3,
            "elements": [
                "minecraft:sea_lantern@0"
            ]
        },
        {
            "x": 5,
            "y": -1,
            "z": -12,
            "elements": [
                "minecraft:sea_lantern@0"
            ]
        },
        {
            "x": -18,
            "y": -1,
            "z": 2,
            "elements": [
                "minecraft:sea_lantern@0"
            ]
        },
        {
            "x": -18,
            "y": -1,
            "z": 9,
            "elements": [
                "extendedcrafting:storage@1"
            ]
        },
        {
            "x": -18,
            "y": -1,
            "z": 8,
            "elements": [
                "extendedcrafting:storage@1"
            ]
        },
        {
            "x": -18,
            "y": -1,
            "z": 7,
            "elements": [
                "minecraft:sea_lantern@0"
            ]
        },
        {
            "x": -18,
            "y": -1,
            "z": 6,
            "elements": [
                "minecraft:sea_lantern@0"
            ]
        },
        {
            "x": -18,
            "y": -1,
            "z": 10,
            "elements": [
                "extendedcrafting:storage@1"
            ]
        },
        {
            "x": 5,
            "y": -1,
            "z": -15,
            "elements": [
                "extendedcrafting:storage@1"
            ]
        },
        {
            "x": 5,
            "y": -1,
            "z": -14,
            "elements": [
                "minecraft:sea_lantern@0"
            ]
        },
        {
            "x": 7,
            "y": 1,
            "z": -13,

            "elements": [
                "modularmachinery:blockcasing@4"
            ]
        },
        {
            "x": -17,
            "y": -2,
            "z": -7,
            "elements": [
                "extendedcrafting:storage@2"
            ]
        },
        {
            "x": -17,
            "y": -2,
            "z": -8,
            "elements": [
                "extendedcrafting:storage@2"
            ]
        },
        {
            "x": -17,
            "y": -2,
            "z": -5,
            "elements": [
                "extendedcrafting:storage@1"
            ]
        },
        {
            "x": -17,
            "y": -2,
            "z": -6,
            "elements": [
                "extendedcrafting:storage@1"
            ]
        },
        {
            "x": -17,
            "y": -2,
            "z": -3,
            "elements": [
                "minecraft:sea_lantern@0"
            ]
        },
        {
            "x": -17,
            "y": -2,
            "z": -4,
            "elements": [
                "minecraft:sea_lantern@0"
            ]
        },
        {
            "x": 4,
            "y": 0,
            "z": 18,
            "elements": [
                "minecraft:sea_lantern@0"
            ]
        },
        {
            "x": -17,
            "y": -2,
            "z": -1,

            "elements": [
                "modularmachinery:blockcasing@4"
            ]
        },
        {
            "x": -17,
            "y": -2,
            "z": -2,
            "elements": [
                "minecraft:sea_lantern@0"
            ]
        },
        {
            "x": -17,
            "y": -2,
            "z": 1,

            "elements": [
                "modularmachinery:blockcasing@4"
            ]
        },
        {
            "x": -17,
            "y": -2,
            "z": 0,

            "elements": [
                "modularmachinery:blockcasing@4"
            ]
        },
        {
            "x": 4,
            "y": 0,
            "z": 19,
            "elements": [
                "minecraft:sea_lantern@0"
            ]
        },
        {
            "x": 4,
            "y": 0,
            "z": 20,

            "elements": [
                "modularmachinery:blockcasing@4"
            ]
        },
        {
            "x": 4,
            "y": 0,
            "z": 21,
            "elements": [
                "minecraft:sea_lantern@0"
            ]
        },
        {
            "x": 7,
            "y": 1,
            "z": 19,

            "elements": [
                "modularmachinery:blockcasing@4"
            ]
        },
        {
            "x": 3,
            "y": 1,
            "z": 2,

            "elements": [
                "modularmachinery:blockcasing@0"
            ]
        },
        {
            "x": 3,
            "y": 1,
            "z": -14,

            "elements": [
                "modularmachinery:blockcasing@4"
            ]
        },
        {
            "x": -14,
            "y": -1,
            "z": 7,
            "elements": [
                "extendedcrafting:storage@0"
            ]
        },
        {
            "x": -14,
            "y": -1,
            "z": 9,
            "elements": [
                "extendedcrafting:storage@0"
            ]
        },
        {
            "x": -14,
            "y": -1,
            "z": 8,
            "elements": [
                "extendedcrafting:storage@0"
            ]
        },
        {
            "x": -14,
            "y": -1,
            "z": 11,
            "elements": [
                "minecraft:sea_lantern@0"
            ]
        },
        {
            "x": -14,
            "y": -1,
            "z": 10,
            "elements": [
                "minecraft:sea_lantern@0"
            ]
        },
        {
            "x": -14,
            "y": -1,
            "z": 13,

            "elements": [
                "modularmachinery:blockcasing@4"
            ]
        },
        {
            "x": -14,
            "y": -1,
            "z": 12,
            "elements": [
                "minecraft:sea_lantern@0"
            ]
        },
        {
            "x": 3,
            "y": 1,
            "z": 20,

            "elements": [
                "modularmachinery:blockcasing@4"
            ]
        },
        {
            "x": -14,
            "y": -1,
            "z": -1,
            "elements": [
                "extendedcrafting:storage@0"
            ]
        },
        {
            "x": -14,
            "y": -1,
            "z": -2,
            "elements": [
                "extendedcrafting:storage@0"
            ]
        },
        {
            "x": 3,
            "y": 1,
            "z": 3,

            "elements": [
                "modularmachinery:blockcasing@0"
            ]
        },
        {
            "x": 3,
            "y": 1,
            "z": 4,

            "elements": [
                "modularmachinery:blockcasing@0"
            ]
        },
        {
            "x": -14,
            "y": -1,
            "z": 15,
            "elements": [
                "minecraft:sea_lantern@0"
            ]
        },
        {
            "x": -14,
            "y": -1,
            "z": 14,
            "elements": [
                "minecraft:sea_lantern@0"
            ]
        },
        {
            "x": -14,
            "y": -1,
            "z": 16,
            "elements": [
                "extendedcrafting:storage@1"
            ]
        },
        {
            "x": -14,
            "y": -1,
            "z": -9,
            "elements": [
                "minecraft:sea_lantern@0"
            ]
        },
        {
            "x": -14,
            "y": -1,
            "z": -10,
            "elements": [
                "extendedcrafting:storage@1"
            ]
        },
        {
            "x": -14,
            "y": -1,
            "z": -7,

            "elements": [
                "modularmachinery:blockcasing@4"
            ]
        },
        {
            "x": -14,
            "y": -1,
            "z": -8,
            "elements": [
                "minecraft:sea_lantern@0"
            ]
        },
        {
            "x": -14,
            "y": -1,
            "z": -5,
            "elements": [
                "minecraft:sea_lantern@0"
            ]
        },
        {
            "x": -14,
            "y": -1,
            "z": -6,
            "elements": [
                "minecraft:sea_lantern@0"
            ]
        },
        {
            "x": -14,
            "y": -1,
            "z": -3,
            "elements": [
                "extendedcrafting:storage@0"
            ]
        },
        {
            "x": -14,
            "y": -1,
            "z": -4,
            "elements": [
                "minecraft:sea_lantern@0"
            ]
        },
        {
            "x": 2,
            "y": -2,
            "z": -16,
            "elements": [
                "extendedcrafting:storage@1"
            ]
        },
        {
            "x": 2,
            "y": -2,
            "z": -17,
            "elements": [
                "extendedcrafting:storage@2"
            ]
        },
        {
            "x": 2,
            "y": -2,
            "z": -14,

            "elements": [
                "modularmachinery:blockcasing@4"
            ]
        },
        {
            "x": 2,
            "y": -2,
            "z": -15,
            "elements": [
                "minecraft:sea_lantern@0"
            ]
        },
        {
            "x": 2,
            "y": -2,
            "z": -12,
            "elements": [
                "extendedcrafting:storage@0"
            ]
        },
        {
            "x": 2,
            "y": -2,
            "z": -13,
            "elements": [
                "minecraft:sea_lantern@0"
            ]
        },
        {
            "x": 2,
            "y": -2,
            "z": -11,
            "elements": [
                "astraladditions:block_starmetal@0"
            ]
        },
        {
            "x": 2,
            "y": -2,
            "z": 23,
            "elements": [
                "extendedcrafting:storage@2"
            ]
        },
        {
            "x": 2,
            "y": -2,
            "z": 18,
            "elements": [
                "extendedcrafting:storage@0"
            ]
        },
        {
            "x": 2,
            "y": -2,
            "z": 17,
            "elements": [
                "astraladditions:block_starmetal@0"
            ]
        },
        {
            "x": 2,
            "y": -2,
            "z": 20,

            "elements": [
                "modularmachinery:blockcasing@4"
            ]
        },
        {
            "x": 2,
            "y": -2,
            "z": 19,
            "elements": [
                "minecraft:sea_lantern@0"
            ]
        },
        {
            "x": 2,
            "y": -2,
            "z": 22,
            "elements": [
                "extendedcrafting:storage@1"
            ]
        },
        {
            "x": 2,
            "y": -2,
            "z": 21,
            "elements": [
                "minecraft:sea_lantern@0"
            ]
        },
        {
            "x": -16,
            "y": 1,
            "z": 10,

            "elements": [
                "modularmachinery:blockcasing@4"
            ]
        },
        {
            "x": -16,
            "y": 1,
            "z": 8,

            "elements": [
                "modularmachinery:blockcasing@4"
            ]
        },
        {
            "x": -1,
            "y": -3,
            "z": -16,
            "elements": [
                "extendedcrafting:storage@1"
            ]
        },
        {
            "x": -16,
            "y": 1,
            "z": 9,

            "elements": [
                "modularmachinery:blockcasing@4"
            ]
        },
        {
            "x": -1,
            "y": -3,
            "z": -15,
            "elements": [
                "minecraft:sea_lantern@0"
            ]
        },
        {
            "x": -1,
            "y": -3,
            "z": -14,

            "elements": [
                "modularmachinery:blockcasing@4"
            ]
        },
        {
            "x": -1,
            "y": -3,
            "z": -13,
            "elements": [
                "minecraft:sea_lantern@0"
            ]
        },
        {
            "x": -1,
            "y": -3,
            "z": -12,
            "elements": [
                "extendedcrafting:storage@0"
            ]
        },
        {
            "x": -16,
            "y": 1,
            "z": -2,

            "elements": [
                "modularmachinery:blockcasing@4"
            ]
        },
        {
            "x": -1,
            "y": -3,
            "z": -4,

            "elements": [
                "modularmachinery:blockcasing@0"
            ]
        },
        {
            "x": -1,
            "y": -3,
            "z": -3,

            "elements": [
                "modularmachinery:blockcasing@0"
            ]
        },
        {
            "x": -1,
            "y": -3,
            "z": 2,

            "elements": [
                "modularmachinery:blockcasing@0"
            ]
        },
        {
            "x": -1,
            "y": -3,
            "z": 3,

            "elements": [
                "modularmachinery:blockcasing@0"
            ]
        },
        {
            "x": 4,
            "y": -4,
            "z": 20,

            "elements": [
                "modularmachinery:blockcasing@4"
            ]
        },
        {
            "x": -1,
            "y": -3,
            "z": 4,

            "elements": [
                "modularmachinery:blockcasing@0"
            ]
        },
        {
            "x": 4,
            "y": -4,
            "z": 19,
            "elements": [
                "minecraft:sea_lantern@0"
            ]
        },
        {
            "x": 4,
            "y": -4,
            "z": 21,
            "elements": [
                "minecraft:sea_lantern@0"
            ]
        },
        {
            "x": 4,
            "y": -4,
            "z": 18,
            "elements": [
                "minecraft:sea_lantern@0"
            ]
        },
        {
            "x": -1,
            "y": -3,
            "z": 10,

            "elements": [
                "modularmachinery:blockcasing@0"
            ]
        },
        {
            "x": -1,
            "y": -3,
            "z": 11,

            "elements": [
                "modularmachinery:blockcasing@0"
            ]
        },
        {
            "x": -1,
            "y": -3,
            "z": 18,
            "elements": [
                "extendedcrafting:storage@0"
            ]
        },
        {
            "x": -1,
            "y": -3,
            "z": 19,
            "elements": [
                "minecraft:sea_lantern@0"
            ]
        },
        {
            "x": -1,
            "y": -3,
            "z": 20,

            "elements": [
                "modularmachinery:blockcasing@4"
            ]
        },
        {
            "x": -1,
            "y": -3,
            "z": 21,
            "elements": [
                "minecraft:sea_lantern@0"
            ]
        },
        {
            "x": -1,
            "y": -3,
            "z": 22,
            "elements": [
                "extendedcrafting:storage@1"
            ]
        },
        {
            "x": 4,
            "y": -4,
            "z": -12,
            "elements": [
                "minecraft:sea_lantern@0"
            ]
        },
        {
            "x": 4,
            "y": -4,
            "z": -13,
            "elements": [
                "minecraft:sea_lantern@0"
            ]
        },
        {
            "x": 4,
            "y": -4,
            "z": -14,

            "elements": [
                "modularmachinery:blockcasing@4"
            ]
        },
        {
            "x": 4,
            "y": -4,
            "z": -15,
            "elements": [
                "minecraft:sea_lantern@0"
            ]
        },
        {
            "x": -2,
            "y": -2,
            "z": 2,

            "elements": [
                "modularmachinery:blockcasing@0"
            ]
        },
        {
            "x": -2,
            "y": -2,
            "z": 3,

            "elements": [
                "modularmachinery:blockcasing@0"
            ]
        },
        {
            "x": -2,
            "y": -2,
            "z": 4,

            "elements": [
                "modularmachinery:blockcasing@0"
            ]
        },
        {
            "x": 0,
            "y": 0,
            "z": 20,

            "elements": [
                "modularmachinery:blockcasing@4"
            ]
        },
        {
            "x": 11,
            "y": 1,
            "z": 16,

            "elements": [
                "modularmachinery:blockcasing@4"
            ]
        },
        {
            "x": 0,
            "y": 0,
            "z": 19,
            "elements": [
                "minecraft:sea_lantern@0"
            ]
        },
        {
            "x": 0,
            "y": 0,
            "z": 21,
            "elements": [
                "minecraft:sea_lantern@0"
            ]
        },
        {
            "x": -2,
            "y": -2,
            "z": -15,
            "elements": [
                "minecraft:sea_lantern@0"
            ]
        },
        {
            "x": -11,
            "y": 0,
            "z": 16,

            "elements": [
                "modularmachinery:blockcasing@4"
            ]
        },
        {
            "x": -2,
            "y": -2,
            "z": -14,

            "elements": [
                "modularmachinery:blockcasing@4"
            ]
        },
        {
            "x": -11,
            "y": 0,
            "z": 17,
            "elements": [
                "minecraft:sea_lantern@0"
            ]
        },
        {
            "x": -2,
            "y": -2,
            "z": -17,
            "elements": [
                "extendedcrafting:storage@2"
            ]
        },
        {
            "x": -11,
            "y": 0,
            "z": 14,
            "elements": [
                "minecraft:sea_lantern@0"
            ]
        },
        {
            "x": 0,
            "y": 0,
            "z": 18,
            "elements": [
                "minecraft:sea_lantern@0"
            ]
        },
        {
            "x": -2,
            "y": -2,
            "z": -16,
            "elements": [
                "extendedcrafting:storage@1"
            ]
        },
        {
            "x": -11,
            "y": 0,
            "z": 15,
            "elements": [
                "minecraft:sea_lantern@0"
            ]
        },
        {
            "x": -2,
            "y": -2,
            "z": -11,
            "elements": [
                "astraladditions:block_starmetal@0"
            ]
        },
        {
            "x": -2,
            "y": -2,
            "z": -13,
            "elements": [
                "minecraft:sea_lantern@0"
            ]
        },
        {
            "x": -11,
            "y": 0,
            "z": 18,
            "elements": [
                "minecraft:sea_lantern@0"
            ]
        },
        {
            "x": -2,
            "y": -2,
            "z": -12,
            "elements": [
                "extendedcrafting:storage@0"
            ]
        },
        {
            "x": 0,
            "y": 0,
            "z": 4,

            "elements": [
                "modularmachinery:blockcasing@0"
            ]
        },
        {
            "x": 9,
            "y": -1,
            "z": -9,
            "elements": [
                "extendedcrafting:storage@0"
            ]
        },
        {
            "x": 0,
            "y": 0,
            "z": 3,

            "elements": [
                "modularmachinery:blockcasing@0"
            ]
        },
        {
            "x": 0,
            "y": 0,
            "z": 6,

            "elements": [
                "modularmachinery:blockcasing@0"
            ]
        },
        {
            "x": 0,
            "y": 0,
            "z": 5,

            "elements": [
                "modularmachinery:blockcasing@0"
            ]
        },
        {
            "x": 0,
            "y": 0,
            "z": 0,

            "elements": [
                "modularmachinery:ivaddition_sky_of_fantasy_controller@2"
            ]
        },
        {
            "x": 0,
            "y": 0,
            "z": 2,

            "elements": [
                "modularmachinery:blockcasing@0"
            ]
        },
        {
            "x": 0,
            "y": 0,
            "z": 1,

            "elements": [
                "modularmachinery:blockcasing@0"
            ]
        },
        {
            "x": 9,
            "y": -1,
            "z": -14,
            "elements": [
                "extendedcrafting:storage@1"
            ]
        },
        {
            "x": 9,
            "y": -1,
            "z": -12,

            "elements": [
                "modularmachinery:blockcasing@4"
            ]
        },
        {
            "x": 9,
            "y": -1,
            "z": -13,
            "elements": [
                "minecraft:sea_lantern@0"
            ]
        },
        {
            "x": 9,
            "y": -1,
            "z": -10,
            "elements": [
                "minecraft:sea_lantern@0"
            ]
        },
        {
            "x": 9,
            "y": -1,
            "z": -11,
            "elements": [
                "minecraft:sea_lantern@0"
            ]
        },
        {
            "x": 0,
            "y": 0,
            "z": -12,
            "elements": [
                "minecraft:sea_lantern@0"
            ]
        },
        {
            "x": 0,
            "y": 0,
            "z": -13,
            "elements": [
                "minecraft:sea_lantern@0"
            ]
        },
        {
            "x": 0,
            "y": 0,
            "z": -14,

            "elements": [
                "modularmachinery:blockcasing@4"
            ]
        },
        {
            "x": 0,
            "y": 0,
            "z": -15,
            "elements": [
                "minecraft:sea_lantern@0"
            ]
        },
        {
            "x": 11,
            "y": 1,
            "z": -10,

            "elements": [
                "modularmachinery:blockcasing@4"
            ]
        },
        {
            "x": -4,
            "y": -4,
            "z": 21,
            "elements": [
                "minecraft:sea_lantern@0"
            ]
        },
        {
            "x": -4,
            "y": -4,
            "z": 20,

            "elements": [
                "modularmachinery:blockcasing@4"
            ]
        },
        {
            "x": -13,
            "y": -2,
            "z": 18,
            "elements": [
                "extendedcrafting:storage@2"
            ]
        },
        {
            "x": -4,
            "y": -4,
            "z": 19,
            "elements": [
                "minecraft:sea_lantern@0"
            ]
        },
        {
            "x": -13,
            "y": -2,
            "z": 17,
            "elements": [
                "extendedcrafting:storage@1"
            ]
        },
        {
            "x": -4,
            "y": -4,
            "z": 18,
            "elements": [
                "minecraft:sea_lantern@0"
            ]
        },
        {
            "x": -13,
            "y": -2,
            "z": 16,
            "elements": [
                "minecraft:sea_lantern@0"
            ]
        },
        {
            "x": -13,
            "y": -2,
            "z": 15,
            "elements": [
                "minecraft:sea_lantern@0"
            ]
        },
        {
            "x": -13,
            "y": -2,
            "z": 14,

            "elements": [
                "modularmachinery:blockcasing@4"
            ]
        },
        {
            "x": 8,
            "y": -4,
            "z": 19,
            "elements": [
                "minecraft:sea_lantern@0"
            ]
        },
        {
            "x": 8,
            "y": -4,
            "z": 18,

            "elements": [
                "modularmachinery:blockcasing@4"
            ]
        },
        {
            "x": 8,
            "y": -4,
            "z": 17,
            "elements": [
                "minecraft:sea_lantern@0"
            ]
        },
        {
            "x": -13,
            "y": -2,
            "z": -1,
            "elements": [
                "astraladditions:block_starmetal@0"
            ]
        },
        {
            "x": -13,
            "y": -2,
            "z": -2,
            "elements": [
                "astraladditions:block_starmetal@0"
            ]
        },
        {
            "x": -13,
            "y": -2,
            "z": 13,
            "elements": [
                "minecraft:sea_lantern@0"
            ]
        },
        {
            "x": -13,
            "y": -2,
            "z": 12,
            "elements": [
                "minecraft:sea_lantern@0"
            ]
        },
        {
            "x": 8,
            "y": -4,
            "z": 4,

            "elements": [
                "modularmachinery:blockcasing@1"
            ]
        },
        {
            "x": -13,
            "y": -2,
            "z": 11,
            "elements": [
                "extendedcrafting:storage@0"
            ]
        },
        {
            "x": -13,
            "y": -2,
            "z": 10,
            "elements": [
                "extendedcrafting:storage@0"
            ]
        },
        {
            "x": -13,
            "y": -2,
            "z": 9,
            "elements": [
                "astraladditions:block_starmetal@0"
            ]
        },
        {
            "x": -13,
            "y": -2,
            "z": 8,
            "elements": [
                "astraladditions:block_starmetal@0"
            ]
        },
        {
            "x": -13,
            "y": -2,
            "z": 7,
            "elements": [
                "astraladditions:block_starmetal@0"
            ]
        },
        {
            "x": -13,
            "y": -2,
            "z": -11,
            "elements": [
                "extendedcrafting:storage@1"
            ]
        },
        {
            "x": -13,
            "y": -2,
            "z": -12,
            "elements": [
                "extendedcrafting:storage@2"
            ]
        },
        {
            "x": -4,
            "y": -4,
            "z": -12,
            "elements": [
                "minecraft:sea_lantern@0"
            ]
        },
        {
            "x": -4,
            "y": -4,
            "z": -13,
            "elements": [
                "minecraft:sea_lantern@0"
            ]
        },
        {
            "x": -4,
            "y": -4,
            "z": -14,

            "elements": [
                "modularmachinery:blockcasing@4"
            ]
        },
        {
            "x": -4,
            "y": -4,
            "z": -15,
            "elements": [
                "minecraft:sea_lantern@0"
            ]
        },
        {
            "x": -13,
            "y": -2,
            "z": -3,
            "elements": [
                "astraladditions:block_starmetal@0"
            ]
        },
        {
            "x": -13,
            "y": -2,
            "z": -4,
            "elements": [
                "extendedcrafting:storage@0"
            ]
        },
        {
            "x": -13,
            "y": -2,
            "z": -5,
            "elements": [
                "extendedcrafting:storage@0"
            ]
        },
        {
            "x": -13,
            "y": -2,
            "z": -6,
            "elements": [
                "minecraft:sea_lantern@0"
            ]
        },
        {
            "x": -13,
            "y": -2,
            "z": -7,
            "elements": [
                "minecraft:sea_lantern@0"
            ]
        },
        {
            "x": -13,
            "y": -2,
            "z": -8,

            "elements": [
                "modularmachinery:blockcasing@4"
            ]
        },
        {
            "x": -13,
            "y": -2,
            "z": -9,
            "elements": [
                "minecraft:sea_lantern@0"
            ]
        },
        {
            "x": -13,
            "y": -2,
            "z": -10,
            "elements": [
                "minecraft:sea_lantern@0"
            ]
        },
        {
            "x": -3,
            "y": -5,
            "z": 20,

            "elements": [
                "modularmachinery:blockcasing@4"
            ]
        },
        {
            "x": -3,
            "y": -5,
            "z": 19,
            "elements": [
                "chisel:futura@4"
            ]
        },
        {
            "x": -3,
            "y": -5,
            "z": 16,
            "elements": [
                "actuallyadditions:block_crystal_empowered@4"
            ]
        },
        {
            "x": -3,
            "y": -5,
            "z": 15,
            "elements": [
                "chisel:futura@4"
            ]
        },
        {
            "x": -3,
            "y": -5,
            "z": 18,
            "elements": [
                "chisel:futura@2"
            ]
        },
        {
            "x": -3,
            "y": -5,
            "z": 17,
            "elements": [
                "chisel:futura@4"
            ]
        },
        {
            "x": -3,
            "y": -5,
            "z": 4,
            "elements": [
                "chisel:futura@4"
            ]
        },
        {
            "x": -3,
            "y": -5,
            "z": 3,
            "elements": [
                "chisel:futura@4"
            ]
        },
        {
            "x": -3,
            "y": -5,
            "z": 6,
            "elements": [
                "chisel:futura@4"
            ]
        },
        {
            "x": -3,
            "y": -5,
            "z": 5,
            "elements": [
                "chisel:futura@4"
            ]
        },
        {
            "x": -3,
            "y": -5,
            "z": 0,
            "elements": [
                "chisel:futura@4"
            ]
        },
        {
            "x": -3,
            "y": -5,
            "z": -1,
            "elements": [
                "actuallyadditions:block_crystal_empowered@0"
            ]
        },
        {
            "x": -3,
            "y": -5,
            "z": 2,
            "elements": [
                "chisel:futura@4"
            ]
        },
        {
            "x": -3,
            "y": -5,
            "z": 1,
            "elements": [
                "chisel:futura@4"
            ]
        },
        {
            "x": -3,
            "y": -5,
            "z": 12,
            "elements": [
                "actuallyadditions:block_crystal_empowered@2"
            ]
        },
        {
            "x": 10,
            "y": -2,
            "z": 13,
            "elements": [
                "astraladditions:block_starmetal@0"
            ]
        },
        {
            "x": -3,
            "y": -5,
            "z": 11,
            "elements": [
                "chisel:futura@4"
            ]
        },
        {
            "x": 10,
            "y": -2,
            "z": 14,
            "elements": [
                "extendedcrafting:storage@0"
            ]
        },
        {
            "x": -3,
            "y": -5,
            "z": 14,
            "elements": [
                "actuallyadditions:block_crystal_empowered@3"
            ]
        },
        {
            "x": -3,
            "y": -5,
            "z": 13,
            "elements": [
                "chisel:futura@4"
            ]
        },
        {
            "x": -3,
            "y": -5,
            "z": 8,
            "elements": [
                "chisel:futura@4"
            ]
        },
        {
            "x": -3,
            "y": -5,
            "z": 7,
            "elements": [
                "actuallyadditions:block_crystal_empowered@0"
            ]
        },
        {
            "x": -3,
            "y": -5,
            "z": 10,
            "elements": [
                "chisel:futura@4"
            ]
        },
        {
            "x": -3,
            "y": -5,
            "z": 9,
            "elements": [
                "actuallyadditions:block_crystal_empowered@1"
            ]
        },
        {
            "x": -3,
            "y": -5,
            "z": -12,
            "elements": [
                "chisel:futura@2"
            ]
        },
        {
            "x": -3,
            "y": -5,
            "z": -13,
            "elements": [
                "chisel:futura@4"
            ]
        },
        {
            "x": -3,
            "y": -5,
            "z": -10,
            "elements": [
                "actuallyadditions:block_crystal_empowered@4"
            ]
        },
        {
            "x": 10,
            "y": -2,
            "z": 19,
            "elements": [
                "extendedcrafting:storage@1"
            ]
        },
        {
            "x": -3,
            "y": -5,
            "z": -11,
            "elements": [
                "chisel:futura@4"
            ]
        },
        {
            "x": 10,
            "y": -2,
            "z": 20,
            "elements": [
                "extendedcrafting:storage@2"
            ]
        },
        {
            "x": 10,
            "y": -2,
            "z": 17,

            "elements": [
                "modularmachinery:blockcasing@4"
            ]
        },
        {
            "x": 10,
            "y": -2,
            "z": 18,
            "elements": [
                "minecraft:sea_lantern@0"
            ]
        },
        {
            "x": -3,
            "y": -5,
            "z": -14,

            "elements": [
                "modularmachinery:blockcasing@4"
            ]
        },
        {
            "x": 10,
            "y": -2,
            "z": 15,
            "elements": [
                "minecraft:sea_lantern@0"
            ]
        },
        {
            "x": 10,
            "y": -2,
            "z": 16,
            "elements": [
                "minecraft:sea_lantern@0"
            ]
        },
        {
            "x": -3,
            "y": -5,
            "z": -4,
            "elements": [
                "chisel:futura@4"
            ]
        },
        {
            "x": -3,
            "y": -5,
            "z": -5,
            "elements": [
                "chisel:futura@4"
            ]
        },
        {
            "x": -3,
            "y": -5,
            "z": -2,
            "elements": [
                "chisel:futura@4"
            ]
        },
        {
            "x": 1,
            "y": 3,
            "z": 3,

            "elements": [
                "modularmachinery:blockcasing@0"
            ]
        },
        {
            "x": -3,
            "y": -5,
            "z": -3,
            "elements": [
                "actuallyadditions:block_crystal_empowered@1"
            ]
        },
        {
            "x": 1,
            "y": 3,
            "z": 4,

            "elements": [
                "modularmachinery:blockcasing@0"
            ]
        },
        {
            "x": -3,
            "y": -5,
            "z": -8,
            "elements": [
                "actuallyadditions:block_crystal_empowered@3"
            ]
        },
        {
            "x": -3,
            "y": -5,
            "z": -9,
            "elements": [
                "chisel:futura@4"
            ]
        },
        {
            "x": -3,
            "y": -5,
            "z": -6,
            "elements": [
                "actuallyadditions:block_crystal_empowered@2"
            ]
        },
        {
            "x": -3,
            "y": -5,
            "z": -7,
            "elements": [
                "chisel:futura@4"
            ]
        },
        {
            "x": -15,
            "y": -4,
            "z": 14,
            "elements": [
                "minecraft:sea_lantern@0"
            ]
        },
        {
            "x": -15,
            "y": -4,
            "z": 15,
            "elements": [
                "minecraft:sea_lantern@0"
            ]
        },
        {
            "x": -15,
            "y": -4,
            "z": 10,
            "elements": [
                "minecraft:sea_lantern@0"
            ]
        },
        {
            "x": 1,
            "y": 3,
            "z": 2,

            "elements": [
                "modularmachinery:blockcasing@0"
            ]
        },
        {
            "x": -15,
            "y": -4,
            "z": 11,

            "elements": [
                "modularmachinery:blockcasing@4"
            ]
        },
        {
            "x": -15,
            "y": -4,
            "z": 12,

            "elements": [
                "modularmachinery:blockcasing@4"
            ]
        },
        {
            "x": -15,
            "y": -4,
            "z": 13,
            "elements": [
                "minecraft:sea_lantern@0"
            ]
        },
        {
            "x": -15,
            "y": -4,
            "z": 6,
            "elements": [
                "minecraft:sea_lantern@0"
            ]
        },
        {
            "x": -15,
            "y": -4,
            "z": 7,
            "elements": [
                "minecraft:sea_lantern@0"
            ]
        },
        {
            "x": -15,
            "y": -4,
            "z": 8,
            "elements": [
                "minecraft:sea_lantern@0"
            ]
        },
        {
            "x": -15,
            "y": -4,
            "z": 9,
            "elements": [
                "minecraft:sea_lantern@0"
            ]
        },
        {
            "x": -15,
            "y": -4,
            "z": 2,
            "elements": [
                "minecraft:sea_lantern@0"
            ]
        },
        {
            "x": -15,
            "y": -4,
            "z": 3,
            "elements": [
                "minecraft:sea_lantern@0"
            ]
        },
        {
            "x": -15,
            "y": -4,
            "z": 4,
            "elements": [
                "minecraft:sea_lantern@0"
            ]
        },
        {
            "x": -15,
            "y": -4,
            "z": 5,
            "elements": [
                "minecraft:sea_lantern@0"
            ]
        },
        {
            "x": 10,
            "y": -2,
            "z": -11,

            "elements": [
                "modularmachinery:blockcasing@4"
            ]
        },
        {
            "x": 10,
            "y": -2,
            "z": -10,
            "elements": [
                "minecraft:sea_lantern@0"
            ]
        },
        {
            "x": 10,
            "y": -2,
            "z": -13,
            "elements": [
                "extendedcrafting:storage@1"
            ]
        },
        {
            "x": 10,
            "y": -2,
            "z": -12,
            "elements": [
                "minecraft:sea_lantern@0"
            ]
        },
        {
            "x": 10,
            "y": -2,
            "z": -14,
            "elements": [
                "extendedcrafting:storage@2"
            ]
        },
        {
            "x": 10,
            "y": -2,
            "z": -7,
            "elements": [
                "astraladditions:block_starmetal@0"
            ]
        },
        {
            "x": 10,
            "y": -2,
            "z": -9,
            "elements": [
                "minecraft:sea_lantern@0"
            ]
        },
        {
            "x": 10,
            "y": -2,
            "z": -8,
            "elements": [
                "extendedcrafting:storage@0"
            ]
        },
        {
            "x": 9,
            "y": -1,
            "z": 16,
            "elements": [
                "minecraft:sea_lantern@0"
            ]
        },
        {
            "x": 9,
            "y": -1,
            "z": 15,
            "elements": [
                "extendedcrafting:storage@0"
            ]
        },
        {
            "x": 9,
            "y": -1,
            "z": 18,

            "elements": [
                "modularmachinery:blockcasing@4"
            ]
        },
        {
            "x": 9,
            "y": -1,
            "z": 17,
            "elements": [
                "minecraft:sea_lantern@0"
            ]
        },
        {
            "x": 9,
            "y": -1,
            "z": 20,
            "elements": [
                "extendedcrafting:storage@1"
            ]
        },
        {
            "x": 9,
            "y": -1,
            "z": 19,
            "elements": [
                "minecraft:sea_lantern@0"
            ]
        },
        {
            "x": -15,
            "y": -4,
            "z": -2,
            "elements": [
                "minecraft:sea_lantern@0"
            ]
        },
        {
            "x": -15,
            "y": -4,
            "z": -1,
            "elements": [
                "minecraft:sea_lantern@0"
            ]
        },
        {
            "x": -14,
            "y": -5,
            "z": 13,

            "elements": [
                "modularmachinery:blockcasing@4"
            ]
        },
        {
            "x": -15,
            "y": -4,
            "z": 0,
            "elements": [
                "minecraft:sea_lantern@0"
            ]
        },
        {
            "x": -14,
            "y": -5,
            "z": 10,
            "elements": [
                "chisel:futura@4"
            ]
        },
        {
            "x": -15,
            "y": -4,
            "z": 1,
            "elements": [
                "minecraft:sea_lantern@0"
            ]
        },
        {
            "x": -14,
            "y": -5,
            "z": 11,
            "elements": [
                "chisel:futura@4"
            ]
        },
        {
            "x": -15,
            "y": -4,
            "z": -6,

            "elements": [
                "modularmachinery:blockcasing@4"
            ]
        },
        {
            "x": -15,
            "y": -4,
            "z": -5,

            "elements": [
                "modularmachinery:blockcasing@4"
            ]
        },
        {
            "x": -15,
            "y": -4,
            "z": -4,
            "elements": [
                "minecraft:sea_lantern@0"
            ]
        },
        {
            "x": -15,
            "y": -4,
            "z": -3,
            "elements": [
                "minecraft:sea_lantern@0"
            ]
        },
        {
            "x": -14,
            "y": -5,
            "z": 4,
            "elements": [
                "chisel:futura@4"
            ]
        },
        {
            "x": -15,
            "y": -4,
            "z": -9,
            "elements": [
                "minecraft:sea_lantern@0"
            ]
        },
        {
            "x": -14,
            "y": -5,
            "z": 5,
            "elements": [
                "chisel:futura@4"
            ]
        },
        {
            "x": -15,
            "y": -4,
            "z": -8,
            "elements": [
                "minecraft:sea_lantern@0"
            ]
        },
        {
            "x": -14,
            "y": -5,
            "z": 2,
            "elements": [
                "chisel:futura@4"
            ]
        },
        {
            "x": -15,
            "y": -4,
            "z": -7,
            "elements": [
                "minecraft:sea_lantern@0"
            ]
        },
        {
            "x": -14,
            "y": -5,
            "z": 3,
            "elements": [
                "chisel:futura@4"
            ]
        },
        {
            "x": -14,
            "y": -5,
            "z": 8,
            "elements": [
                "chisel:futura@2"
            ]
        },
        {
            "x": -14,
            "y": -5,
            "z": 9,
            "elements": [
                "chisel:futura@2"
            ]
        },
        {
            "x": -14,
            "y": -5,
            "z": 6,
            "elements": [
                "chisel:futura@4"
            ]
        },
        {
            "x": -14,
            "y": -5,
            "z": 7,
            "elements": [
                "chisel:futura@2"
            ]
        },
        {
            "x": -14,
            "y": -5,
            "z": -4,
            "elements": [
                "chisel:futura@4"
            ]
        },
        {
            "x": -14,
            "y": -5,
            "z": -3,
            "elements": [
                "chisel:futura@2"
            ]
        },
        {
            "x": -14,
            "y": -5,
            "z": -5,
            "elements": [
                "chisel:futura@4"
            ]
        },
        {
            "x": -14,
            "y": -5,
            "z": 0,
            "elements": [
                "chisel:futura@4"
            ]
        },
        {
            "x": -14,
            "y": -5,
            "z": 1,
            "elements": [
                "chisel:futura@4"
            ]
        },
        {
            "x": -14,
            "y": -5,
            "z": -2,
            "elements": [
                "chisel:futura@2"
            ]
        },
        {
            "x": -14,
            "y": -5,
            "z": -1,
            "elements": [
                "chisel:futura@2"
            ]
        },
        {
            "x": -14,
            "y": -5,
            "z": -7,

            "elements": [
                "modularmachinery:blockcasing@4"
            ]
        },
        {
            "x": -1,
            "y": 1,
            "z": 20,

            "elements": [
                "modularmachinery:blockcasing@4"
            ]
        },
        {
            "x": -1,
            "y": 1,
            "z": -14,

            "elements": [
                "modularmachinery:blockcasing@4"
            ]
        },
        {
            "x": -1,
            "y": 1,
            "z": 6,

            "elements": [
                "modularmachinery:blockcasing@0"
            ]
        },
        {
            "x": -1,
            "y": 1,
            "z": 5,

            "elements": [
                "modularmachinery:blockcasing@0"
            ]
        },
        {
            "x": -1,
            "y": 1,
            "z": 4,

            "elements": [
                "modularmachinery:blockcasing@0"
            ]
        },
        {
            "x": -7,
            "y": 0,
            "z": 17,
            "elements": [
                "minecraft:sea_lantern@0"
            ]
        },
        {
            "x": -1,
            "y": 1,
            "z": 3,

            "elements": [
                "modularmachinery:blockcasing@0"
            ]
        },
        {
            "x": -1,
            "y": 1,
            "z": 2,

            "elements": [
                "modularmachinery:blockcasing@0"
            ]
        },
        {
            "x": -7,
            "y": 0,
            "z": 19,

            "elements": [
                "modularmachinery:blockcasing@4"
            ]
        },
        {
            "x": -1,
            "y": 1,
            "z": 1,

            "elements": [
                "modularmachinery:blockcasing@0"
            ]
        },
        {
            "x": -7,
            "y": 0,
            "z": 18,
            "elements": [
                "minecraft:sea_lantern@0"
            ]
        },
        {
            "x": -1,
            "y": 1,
            "z": 0,

            "elements": [
                "modularmachinery:blockcasing@0"
            ]
        },
        {
            "x": -7,
            "y": 0,
            "z": 20,
            "elements": [
                "minecraft:sea_lantern@0"
            ]
        },
        {
            "x": 8,
            "y": -4,
            "z": 2,

            "elements": [
                "modularmachinery:blockcasing@1"
            ]
        },
        {
            "x": 8,
            "y": -4,
            "z": -11,
            "elements": [
                "minecraft:sea_lantern@0"
            ]
        },
        {
            "x": 8,
            "y": -4,
            "z": -12,

            "elements": [
                "modularmachinery:blockcasing@4"
            ]
        },
        {
            "x": 8,
            "y": -4,
            "z": -13,
            "elements": [
                "minecraft:sea_lantern@0"
            ]
        },
        {
            "x": -7,
            "y": 0,
            "z": -13,

            "elements": [
                "modularmachinery:blockcasing@4"
            ]
        },
        {
            "x": -7,
            "y": 0,
            "z": -14,
            "elements": [
                "minecraft:sea_lantern@0"
            ]
        },
        {
            "x": -7,
            "y": 0,
            "z": -11,
            "elements": [
                "minecraft:sea_lantern@0"
            ]
        },
        {
            "x": -7,
            "y": 0,
            "z": -12,
            "elements": [
                "minecraft:sea_lantern@0"
            ]
        },
        {
            "x": -12,
            "y": 1,
            "z": 15,

            "elements": [
                "modularmachinery:blockcasing@4"
            ]
        },
        {
            "x": 3,
            "y": -3,
            "z": -12,
            "elements": [
                "extendedcrafting:storage@0"
            ]
        },
        {
            "x": 3,
            "y": -3,
            "z": -13,
            "elements": [
                "minecraft:sea_lantern@0"
            ]
        },
        {
            "x": 3,
            "y": -3,
            "z": -14,

            "elements": [
                "modularmachinery:blockcasing@4"
            ]
        },
        {
            "x": 3,
            "y": -3,
            "z": -15,
            "elements": [
                "minecraft:sea_lantern@0"
            ]
        },
        {
            "x": 3,
            "y": -3,
            "z": -16,
            "elements": [
                "extendedcrafting:storage@1"
            ]
        },
        {
            "x": -12,
            "y": 1,
            "z": -9,

            "elements": [
                "modularmachinery:blockcasing@4"
            ]
        },
        {
            "x": -2,
            "y": -2,
            "z": 17,
            "elements": [
                "astraladditions:block_starmetal@0"
            ]
        },
        {
            "x": -2,
            "y": -2,
            "z": 18,
            "elements": [
                "extendedcrafting:storage@0"
            ]
        },
        {
            "x": -2,
            "y": -2,
            "z": 21,
            "elements": [
                "minecraft:sea_lantern@0"
            ]
        },
        {
            "x": -2,
            "y": -2,
            "z": 22,
            "elements": [
                "extendedcrafting:storage@1"
            ]
        },
        {
            "x": -2,
            "y": -2,
            "z": 19,
            "elements": [
                "minecraft:sea_lantern@0"
            ]
        },
        {
            "x": -2,
            "y": -2,
            "z": 20,

            "elements": [
                "modularmachinery:blockcasing@4"
            ]
        },
        {
            "x": -2,
            "y": -2,
            "z": 23,
            "elements": [
                "extendedcrafting:storage@2"
            ]
        },
        {
            "x": -5,
            "y": 1,
            "z": -13,

            "elements": [
                "modularmachinery:blockcasing@4"
            ]
        },
        {
            "x": 14,
            "y": -2,
            "z": 8,
            "elements": [
                "extendedcrafting:storage@0"
            ]
        },
        {
            "x": 14,
            "y": -2,
            "z": 7,
            "elements": [
                "extendedcrafting:storage@0"
            ]
        },
        {
            "x": 14,
            "y": -2,
            "z": 10,
            "elements": [
                "minecraft:sea_lantern@0"
            ]
        },
        {
            "x": 14,
            "y": -2,
            "z": 9,
            "elements": [
                "extendedcrafting:storage@0"
            ]
        },
        {
            "x": -8,
            "y": -3,
            "z": 2,

            "elements": [
                "modularmachinery:blockcasing@0"
            ]
        },
        {
            "x": 14,
            "y": -2,
            "z": 4,
            "elements": [
                "astraladditions:block_starmetal@0"
            ]
        },
        {
            "x": 14,
            "y": -2,
            "z": 3,
            "elements": [
                "astraladditions:block_starmetal@0"
            ]
        },
        {
            "x": -8,
            "y": -3,
            "z": 4,

            "elements": [
                "modularmachinery:blockcasing@0"
            ]
        },
        {
            "x": 14,
            "y": -2,
            "z": 6,
            "elements": [
                "astraladditions:block_starmetal@0"
            ]
        },
        {
            "x": 14,
            "y": -2,
            "z": 5,
            "elements": [
                "astraladditions:block_starmetal@0"
            ]
        },
        {
            "x": 14,
            "y": -2,
            "z": 0,
            "elements": [
                "astraladditions:block_starmetal@0"
            ]
        },
        {
            "x": 14,
            "y": -2,
            "z": -1,
            "elements": [
                "extendedcrafting:storage@0"
            ]
        },
        {
            "x": 14,
            "y": -2,
            "z": 2,
            "elements": [
                "astraladditions:block_starmetal@0"
            ]
        },
        {
            "x": 14,
            "y": -2,
            "z": 1,
            "elements": [
                "astraladditions:block_starmetal@0"
            ]
        },
        {
            "x": 14,
            "y": -2,
            "z": -4,
            "elements": [
                "minecraft:sea_lantern@0"
            ]
        },
        {
            "x": 14,
            "y": -2,
            "z": -5,
            "elements": [
                "minecraft:sea_lantern@0"
            ]
        },
        {
            "x": 14,
            "y": -2,
            "z": -2,
            "elements": [
                "extendedcrafting:storage@0"
            ]
        },
        {
            "x": 14,
            "y": -2,
            "z": -3,
            "elements": [
                "extendedcrafting:storage@0"
            ]
        },
        {
            "x": 12,
            "y": -4,
            "z": -11,
            "elements": [
                "minecraft:sea_lantern@0"
            ]
        },
        {
            "x": -8,
            "y": -3,
            "z": 18,

            "elements": [
                "modularmachinery:blockcasing@4"
            ]
        },
        {
            "x": -8,
            "y": -3,
            "z": 19,
            "elements": [
                "minecraft:sea_lantern@0"
            ]
        },
        {
            "x": -8,
            "y": -3,
            "z": 20,
            "elements": [
                "extendedcrafting:storage@1"
            ]
        },
        {
            "x": 12,
            "y": -4,
            "z": -12,
            "elements": [
                "minecraft:sea_lantern@0"
            ]
        },
        {
            "x": 12,
            "y": -4,
            "z": -7,
            "elements": [
                "minecraft:sea_lantern@0"
            ]
        },
        {
            "x": 14,
            "y": -2,
            "z": 16,
            "elements": [
                "extendedcrafting:storage@1"
            ]
        },
        {
            "x": 14,
            "y": -2,
            "z": 15,
            "elements": [
                "minecraft:sea_lantern@0"
            ]
        },
        {
            "x": 12,
            "y": -4,
            "z": -9,

            "elements": [
                "modularmachinery:blockcasing@4"
            ]
        },
        {
            "x": -8,
            "y": -3,
            "z": 16,
            "elements": [
                "extendedcrafting:storage@0"
            ]
        },
        {
            "x": 12,
            "y": -4,
            "z": -8,
            "elements": [
                "minecraft:sea_lantern@0"
            ]
        },
        {
            "x": -8,
            "y": -3,
            "z": 17,
            "elements": [
                "minecraft:sea_lantern@0"
            ]
        },
        {
            "x": 14,
            "y": -2,
            "z": 17,
            "elements": [
                "extendedcrafting:storage@2"
            ]
        },
        {
            "x": 14,
            "y": -2,
            "z": 12,
            "elements": [
                "minecraft:sea_lantern@0"
            ]
        },
        {
            "x": 14,
            "y": -2,
            "z": 11,
            "elements": [
                "minecraft:sea_lantern@0"
            ]
        },
        {
            "x": 14,
            "y": -2,
            "z": 14,
            "elements": [
                "minecraft:sea_lantern@0"
            ]
        },
        {
            "x": 14,
            "y": -2,
            "z": 13,

            "elements": [
                "modularmachinery:blockcasing@4"
            ]
        },
        {
            "x": -5,
            "y": 1,
            "z": 19,

            "elements": [
                "modularmachinery:blockcasing@4"
            ]
        },
        {
            "x": -6,
            "y": -1,
            "z": 21,
            "elements": [
                "extendedcrafting:storage@1"
            ]
        },
        {
            "x": -6,
            "y": -1,
            "z": 20,
            "elements": [
                "minecraft:sea_lantern@0"
            ]
        },
        {
            "x": -6,
            "y": -1,
            "z": 19,

            "elements": [
                "modularmachinery:blockcasing@4"
            ]
        },
        {
            "x": -6,
            "y": -1,
            "z": 18,
            "elements": [
                "minecraft:sea_lantern@0"
            ]
        },
        {
            "x": 12,
            "y": -4,
            "z": 13,
            "elements": [
                "minecraft:sea_lantern@0"
            ]
        },
        {
            "x": -6,
            "y": -1,
            "z": 17,
            "elements": [
                "extendedcrafting:storage@0"
            ]
        },
        {
            "x": 12,
            "y": -4,
            "z": 14,
            "elements": [
                "minecraft:sea_lantern@0"
            ]
        },
        {
            "x": -8,
            "y": -3,
            "z": -10,
            "elements": [
                "extendedcrafting:storage@0"
            ]
        },
        {
            "x": 12,
            "y": -4,
            "z": 17,
            "elements": [
                "minecraft:sea_lantern@0"
            ]
        },
        {
            "x": 12,
            "y": -4,
            "z": 18,
            "elements": [
                "minecraft:sea_lantern@0"
            ]
        },
        {
            "x": 12,
            "y": -4,
            "z": 15,

            "elements": [
                "modularmachinery:blockcasing@4"
            ]
        },
        {
            "x": 12,
            "y": -4,
            "z": 16,
            "elements": [
                "minecraft:sea_lantern@0"
            ]
        },
        {
            "x": -8,
            "y": -3,
            "z": -14,
            "elements": [
                "extendedcrafting:storage@1"
            ]
        },
        {
            "x": -8,
            "y": -3,
            "z": -13,
            "elements": [
                "minecraft:sea_lantern@0"
            ]
        },
        {
            "x": -8,
            "y": -3,
            "z": -12,

            "elements": [
                "modularmachinery:blockcasing@4"
            ]
        },
        {
            "x": -8,
            "y": -3,
            "z": -11,
            "elements": [
                "minecraft:sea_lantern@0"
            ]
        },
        {
            "x": -7,
            "y": -1,
            "z": 4,

            "elements": [
                "modularmachinery:blockcasing@0"
            ]
        },
        {
            "x": -7,
            "y": -1,
            "z": 2,

            "elements": [
                "modularmachinery:blockcasing@0"
            ]
        },
        {
            "x": -7,
            "y": -1,
            "z": -12,
            "elements": [
                "minecraft:sea_lantern@0"
            ]
        },
        {
            "x": -7,
            "y": -1,
            "z": -13,

            "elements": [
                "modularmachinery:blockcasing@4"
            ]
        },
        {
            "x": -7,
            "y": -1,
            "z": -10,
            "elements": [
                "extendedcrafting:storage@0"
            ]
        },
        {
            "x": -7,
            "y": -1,
            "z": -11,
            "elements": [
                "minecraft:sea_lantern@0"
            ]
        },
        {
            "x": -7,
            "y": -1,
            "z": -14,
            "elements": [
                "minecraft:sea_lantern@0"
            ]
        },
        {
            "x": -7,
            "y": -1,
            "z": -15,
            "elements": [
                "extendedcrafting:storage@1"
            ]
        },
        {
            "x": 13,
            "y": -2,
            "z": 8,
            "elements": [
                "astraladditions:block_starmetal@0"
            ]
        },
        {
            "x": 13,
            "y": -2,
            "z": 9,
            "elements": [
                "astraladditions:block_starmetal@0"
            ]
        },
        {
            "x": 13,
            "y": -2,
            "z": 10,
            "elements": [
                "extendedcrafting:storage@0"
            ]
        },
        {
            "x": 13,
            "y": -2,
            "z": 11,
            "elements": [
                "extendedcrafting:storage@0"
            ]
        },
        {
            "x": 13,
            "y": -2,
            "z": 7,
            "elements": [
                "astraladditions:block_starmetal@0"
            ]
        },
        {
            "x": 13,
            "y": -2,
            "z": 16,
            "elements": [
                "minecraft:sea_lantern@0"
            ]
        },
        {
            "x": 13,
            "y": -2,
            "z": 17,
            "elements": [
                "extendedcrafting:storage@1"
            ]
        },
        {
            "x": 13,
            "y": -2,
            "z": 18,
            "elements": [
                "extendedcrafting:storage@2"
            ]
        },
        {
            "x": 13,
            "y": -2,
            "z": 12,
            "elements": [
                "minecraft:sea_lantern@0"
            ]
        },
        {
            "x": 13,
            "y": -2,
            "z": 13,
            "elements": [
                "minecraft:sea_lantern@0"
            ]
        },
        {
            "x": 13,
            "y": -2,
            "z": 14,

            "elements": [
                "modularmachinery:blockcasing@4"
            ]
        },
        {
            "x": 13,
            "y": -2,
            "z": 15,
            "elements": [
                "minecraft:sea_lantern@0"
            ]
        },
        {
            "x": 13,
            "y": -2,
            "z": -8,

            "elements": [
                "modularmachinery:blockcasing@4"
            ]
        },
        {
            "x": 13,
            "y": -2,
            "z": -7,
            "elements": [
                "minecraft:sea_lantern@0"
            ]
        },
        {
            "x": 13,
            "y": -2,
            "z": -6,
            "elements": [
                "minecraft:sea_lantern@0"
            ]
        },
        {
            "x": 13,
            "y": -2,
            "z": -5,
            "elements": [
                "extendedcrafting:storage@0"
            ]
        },
        {
            "x": 13,
            "y": -2,
            "z": -12,
            "elements": [
                "extendedcrafting:storage@2"
            ]
        },
        {
            "x": 13,
            "y": -2,
            "z": -11,
            "elements": [
                "extendedcrafting:storage@1"
            ]
        },
        {
            "x": 13,
            "y": -2,
            "z": -10,
            "elements": [
                "minecraft:sea_lantern@0"
            ]
        },
        {
            "x": 13,
            "y": -2,
            "z": -4,
            "elements": [
                "extendedcrafting:storage@0"
            ]
        },
        {
            "x": 13,
            "y": -2,
            "z": -3,
            "elements": [
                "astraladditions:block_starmetal@0"
            ]
        },
        {
            "x": 13,
            "y": -2,
            "z": -2,
            "elements": [
                "astraladditions:block_starmetal@0"
            ]
        },
        {
            "x": 13,
            "y": -2,
            "z": -1,
            "elements": [
                "astraladditions:block_starmetal@0"
            ]
        },
        {
            "x": 16,
            "y": -1,
            "z": -4,

            "elements": [
                "modularmachinery:blockcasing@4"
            ]
        },
        {
            "x": 16,
            "y": -1,
            "z": -3,

            "elements": [
                "modularmachinery:blockcasing@4"
            ]
        },
        {
            "x": 16,
            "y": -1,
            "z": -2,

            "elements": [
                "modularmachinery:blockcasing@4"
            ]
        },
        {
            "x": 16,
            "y": -1,
            "z": -1,
            "elements": [
                "minecraft:sea_lantern@0"
            ]
        },
        {
            "x": 16,
            "y": -1,
            "z": -8,
            "elements": [
                "extendedcrafting:storage@1"
            ]
        },
        {
            "x": 16,
            "y": -1,
            "z": -7,
            "elements": [
                "extendedcrafting:storage@1"
            ]
        },
        {
            "x": 16,
            "y": -1,
            "z": -6,
            "elements": [
                "minecraft:sea_lantern@0"
            ]
        },
        {
            "x": 16,
            "y": -1,
            "z": -5,
            "elements": [
                "minecraft:sea_lantern@0"
            ]
        },
        {
            "x": 16,
            "y": -1,
            "z": 12,
            "elements": [
                "minecraft:sea_lantern@0"
            ]
        },
        {
            "x": 16,
            "y": -1,
            "z": 13,
            "elements": [
                "extendedcrafting:storage@1"
            ]
        },
        {
            "x": 16,
            "y": -1,
            "z": 14,
            "elements": [
                "extendedcrafting:storage@1"
            ]
        },
        {
            "x": 16,
            "y": -1,
            "z": 8,

            "elements": [
                "modularmachinery:blockcasing@4"
            ]
        },
        {
            "x": 16,
            "y": -1,
            "z": 9,

            "elements": [
                "modularmachinery:blockcasing@4"
            ]
        },
        {
            "x": 16,
            "y": -1,
            "z": 10,

            "elements": [
                "modularmachinery:blockcasing@4"
            ]
        },
        {
            "x": 16,
            "y": -1,
            "z": 11,
            "elements": [
                "minecraft:sea_lantern@0"
            ]
        },
        {
            "x": 16,
            "y": -1,
            "z": 4,
            "elements": [
                "minecraft:sea_lantern@0"
            ]
        },
        {
            "x": 16,
            "y": -1,
            "z": 5,
            "elements": [
                "minecraft:sea_lantern@0"
            ]
        },
        {
            "x": 16,
            "y": -1,
            "z": 6,
            "elements": [
                "minecraft:sea_lantern@0"
            ]
        },
        {
            "x": 16,
            "y": -1,
            "z": 7,
            "elements": [
                "minecraft:sea_lantern@0"
            ]
        },
        {
            "x": 16,
            "y": -1,
            "z": 0,
            "elements": [
                "minecraft:sea_lantern@0"
            ]
        },
        {
            "x": 16,
            "y": -1,
            "z": 1,
            "elements": [
                "minecraft:sea_lantern@0"
            ]
        },
        {
            "x": 16,
            "y": -1,
            "z": 2,
            "elements": [
                "minecraft:sea_lantern@0"
            ]
        },
        {
            "x": 16,
            "y": -1,
            "z": 3,
            "elements": [
                "minecraft:sea_lantern@0"
            ]
        },
        {
            "x": -4,
            "y": 1,
            "z": -14,

            "elements": [
                "modularmachinery:blockcasing@4"
            ]
        },
        {
            "x": -4,
            "y": 1,
            "z": 20,

            "elements": [
                "modularmachinery:blockcasing@4"
            ]
        },
        {
            "x": 15,
            "y": 0,
            "z": 14,
            "elements": [
                "minecraft:sea_lantern@0"
            ]
        },
        {
            "x": 15,
            "y": 0,
            "z": 13,
            "elements": [
                "minecraft:sea_lantern@0"
            ]
        },
        {
            "x": 15,
            "y": 0,
            "z": 12,

            "elements": [
                "modularmachinery:blockcasing@4"
            ]
        },
        {
            "x": 15,
            "y": -3,
            "z": -6,

            "elements": [
                "modularmachinery:blockcasing@4"
            ]
        },
        {
            "x": 15,
            "y": 0,
            "z": 11,

            "elements": [
                "modularmachinery:blockcasing@4"
            ]
        },
        {
            "x": 15,
            "y": -3,
            "z": -7,
            "elements": [
                "minecraft:sea_lantern@0"
            ]
        },
        {
            "x": 15,
            "y": 0,
            "z": 10,
            "elements": [
                "minecraft:sea_lantern@0"
            ]
        },
        {
            "x": 15,
            "y": -3,
            "z": -8,
            "elements": [
                "minecraft:sea_lantern@0"
            ]
        },
        {
            "x": 15,
            "y": 0,
            "z": 9,
            "elements": [
                "minecraft:sea_lantern@0"
            ]
        },
        {
            "x": 15,
            "y": -3,
            "z": -9,
            "elements": [
                "extendedcrafting:storage@1"
            ]
        },
        {
            "x": 15,
            "y": 0,
            "z": 8,
            "elements": [
                "minecraft:sea_lantern@0"
            ]
        },
        {
            "x": 15,
            "y": 0,
            "z": 7,
            "elements": [
                "minecraft:sea_lantern@0"
            ]
        },
        {
            "x": 15,
            "y": 0,
            "z": 6,
            "elements": [
                "minecraft:sea_lantern@0"
            ]
        },
        {
            "x": 15,
            "y": 0,
            "z": 5,
            "elements": [
                "minecraft:sea_lantern@0"
            ]
        },
        {
            "x": 15,
            "y": 0,
            "z": 4,
            "elements": [
                "minecraft:sea_lantern@0"
            ]
        },
        {
            "x": 15,
            "y": 0,
            "z": 3,
            "elements": [
                "minecraft:sea_lantern@0"
            ]
        },
        {
            "x": 15,
            "y": 0,
            "z": 2,
            "elements": [
                "minecraft:sea_lantern@0"
            ]
        },
        {
            "x": 15,
            "y": 0,
            "z": 1,
            "elements": [
                "minecraft:sea_lantern@0"
            ]
        },
        {
            "x": 15,
            "y": 0,
            "z": 0,
            "elements": [
                "minecraft:sea_lantern@0"
            ]
        },
        {
            "x": 15,
            "y": 0,
            "z": -1,
            "elements": [
                "minecraft:sea_lantern@0"
            ]
        },
        {
            "x": 15,
            "y": 0,
            "z": -2,
            "elements": [
                "minecraft:sea_lantern@0"
            ]
        },
        {
            "x": 15,
            "y": 0,
            "z": -3,
            "elements": [
