{   
    "registryname": "ivaddition_stardust",
    "localizedname": "星陨秘仪",
    "color": "FF33FF",
    "parts": [
        {
            "x": -5,
            "y": 14,
            "z": 8,
            "elements": [
                "astraladditions:block_starmetal@0"
            ]
        },
        {
            "x": -5,
            "y": 14,
            "z": 9,
            "elements": [
                "astraladditions:block_starmetal@0"
            ]
        },
        {
            "x": -5,
            "y": 14,
            "z": 7,
            "elements": [
                "astraladditions:block_starmetal@0"
            ]
        },
        {
            "x": -5,
            "y": 14,
            "z": 13,
            "elements": [
                "integratedterminals:menril_glass@0"
            ]
        },
        {
            "x": -5,
            "y": 14,
            "z": 14,
            "elements": [
                "deepmoblearning:infused_ingot_block@0"
            ]
        },
        {
            "x": 15,
            "y": 13,
            "z": 3,
            "elements": [
                "deepmoblearning:infused_ingot_block@0"
            ]
        },
        {
            "x": 19,
            "y": 17,
            "z": 10,
            "elements": [
                "contenttweaker:sky_block@0"
            ]
        },
        {
            "x": 15,
            "y": 13,
            "z": -2,
            "elements": [
                "deepmoblearning:infused_ingot_block@0"
            ]
        },
        {
            "x": 19,
            "y": 17,
            "z": 8,
            "elements": [
                "minecraft:purpur_block@0"
            ]
        },
        {
            "x": 15,
            "y": 13,
            "z": -3,
            "elements": [
                "deepmoblearning:infused_ingot_block@0"
            ]
        },
        {
            "x": 15,
            "y": 13,
            "z": 0,
            "elements": [
                "deepmoblearning:infused_ingot_block@0"
            ]
        },
        {
            "x": 19,
            "y": 17,
            "z": 6,
            "elements": [
                "contenttweaker:sky_block@0"
            ]
        },
        {
            "x": 15,
            "y": 13,
            "z": -1,
            "elements": [
                "deepmoblearning:infused_ingot_block@0"
            ]
        },
        {
            "x": 15,
            "y": 13,
            "z": 2,
            "elements": [
                "deepmoblearning:infused_ingot_block@0"
            ]
        },
        {
            "x": 15,
            "y": 13,
            "z": 1,
            "elements": [
                "deepmoblearning:infused_ingot_block@0"
            ]
        },
        {
            "x": -9,
            "y": 10,
            "z": -9,
            "elements": [
                "tp:netherstar_block@0"
            ]
        },
        {
            "x": -9,
            "y": 10,
            "z": -8,
            "elements": [
                "tp:netherstar_block@0"
            ]
        },
        {
            "x": -9,
            "y": 10,
            "z": -7,
            "elements": [
                "tp:netherstar_block@0"
            ]
        },
        {
            "x": -18,
            "y": -1,
            "z": -19,
            "elements": [
                "tp:netherstar_block@0"
            ]
        },
        {
            "x": -1,
            "y": 18,
            "z": 17,
            "elements": [
                "prodigytech:zorrasteel_block@0"
            ]
        },
        {
            "x": -9,
            "y": 10,
            "z": -11,
            "elements": [
                "integratedterminals:menril_glass@0"
            ]
        },
        {
            "x": -9,
            "y": 10,
            "z": -18,
            "elements": [
                "tp:netherstar_block@0"
            ]
        },
        {
            "x": -1,
            "y": 18,
            "z": 19,
            "elements": [
                "prodigytech:zorrasteel_block@0"
            ]
        },
        {
            "x": -9,
            "y": 10,
            "z": -17,
            "elements": [
                "tp:netherstar_block@0"
            ]
        },
        {
            "x": -1,
            "y": 18,
            "z": 18,
            "elements": [
                "prodigytech:zorrasteel_block@0"
            ]
        },
        {
            "x": -18,
            "y": -1,
            "z": -17,
            "elements": [
                "tp:netherstar_block@0"
            ]
        },
        {
            "x": -18,
            "y": -1,
            "z": -18,
            "elements": [
                "tp:netherstar_block@0"
            ]
        },
        {
            "x": -9,
            "y": 10,
            "z": 11,
            "elements": [
                "integratedterminals:menril_glass@0"
            ]
        },
        {
            "x": 20,
            "y": 20,
            "z": -2,
            "elements": [
                "tp:hardened_stone_bricks@0"
            ]
        },
        {
            "x": -18,
            "y": -1,
            "z": -7,
            "elements": [
                "tp:netherstar_block@0"
            ]
        },
        {
            "x": -18,
            "y": -1,
            "z": -8,
            "elements": [
                "tp:netherstar_block@0"
            ]
        },
        {
            "x": -9,
            "y": 10,
            "z": 7,
            "elements": [
                "tp:netherstar_block@0"
            ]
        },
        {
            "x": -18,
            "y": -1,
            "z": -9,
            "elements": [
                "tp:netherstar_block@0"
            ]
        },
        {
            "x": -9,
            "y": 10,
            "z": 8,
            "elements": [
                "tp:netherstar_block@0"
            ]
        },
        {
            "x": 20,
            "y": 20,
            "z": -6,
            "elements": [
                "contenttweaker:sky_block@0"
            ]
        },
        {
            "x": -9,
            "y": 10,
            "z": 9,
            "elements": [
                "tp:netherstar_block@0"
            ]
        },
        {
            "x": 20,
            "y": 20,
            "z": -10,
            "elements": [
                "contenttweaker:sky_block@0"
            ]
        },
        {
            "x": -18,
            "y": -1,
            "z": 9,
            "elements": [
                "tp:netherstar_block@0"
            ]
        },
        {
            "x": -18,
            "y": -1,
            "z": 8,
            "elements": [
                "tp:netherstar_block@0"
            ]
        },
        {
            "x": -18,
            "y": -1,
            "z": 7,
            "elements": [
                "tp:netherstar_block@0"
            ]
        },
        {
            "x": -18,
            "y": -1,
            "z": 17,
            "elements": [
                "tp:netherstar_block@0"
            ]
        },
        {
            "x": -5,
            "y": 14,
            "z": -14,
            "elements": [
                "deepmoblearning:infused_ingot_block@0"
            ]
        },
        {
            "x": -5,
            "y": 14,
            "z": -13,
            "elements": [
                "integratedterminals:menril_glass@0"
            ]
        },
        {
            "x": -5,
            "y": 14,
            "z": -8,
            "elements": [
                "astraladditions:block_starmetal@0"
            ]
        },
        {
            "x": -5,
            "y": 14,
            "z": -7,
            "elements": [
                "astraladditions:block_starmetal@0"
            ]
        },
        {
            "x": -18,
            "y": -1,
            "z": 19,
            "elements": [
                "tp:netherstar_block@0"
            ]
        },
        {
            "x": -9,
            "y": 10,
            "z": -19,
            "elements": [
                "tp:netherstar_block@0"
            ]
        },
        {
            "x": -5,
            "y": 14,
            "z": -9,
            "elements": [
                "astraladditions:block_starmetal@0"
            ]
        },
        {
            "x": -18,
            "y": -1,
            "z": 18,
            "elements": [
                "tp:netherstar_block@0"
            ]
        },
        {
            "x": -13,
            "y": 6,
            "z": -19,
            "elements": [
                "extendedcrafting:storage@1"
            ]
        },
        {
            "x": -4,
            "y": 17,
            "z": 13,
            "elements": [
                "integratedterminals:menril_glass@0"
            ]
        },
        {
            "x": -4,
            "y": 17,
            "z": 14,
            "elements": [
                "deepmoblearning:infused_ingot_block@0"
            ]
        },
        {
            "x": -13,
            "y": 6,
            "z": -18,
            "elements": [
                "extendedcrafting:storage@1"
            ]
        },
        {
            "x": -13,
            "y": 6,
            "z": -17,
            "elements": [
                "extendedcrafting:storage@1"
            ]
        },
        {
            "x": -13,
            "y": 6,
            "z": 8,
            "elements": [
                "extendedcrafting:storage@1"
            ]
        },
        {
            "x": -13,
            "y": 6,
            "z": 9,
            "elements": [
                "extendedcrafting:storage@1"
            ]
        },
        {
            "x": -13,
            "y": 6,
            "z": 7,
            "elements": [
                "extendedcrafting:storage@1"
            ]
        },
        {
            "x": 20,
            "y": 20,
            "z": 10,
            "elements": [
                "contenttweaker:sky_block@0"
            ]
        },
        {
            "x": -1,
            "y": 18,
            "z": -17,
            "elements": [
                "prodigytech:zorrasteel_block@0"
            ]
        },
        {
            "x": 14,
            "y": 10,
            "z": 2,
            "elements": [
                "integratedterminals:menril_glass@0"
            ]
        },
        {
            "x": -1,
            "y": 18,
            "z": -18,
            "elements": [
                "prodigytech:zorrasteel_block@0"
            ]
        },
        {
            "x": 14,
            "y": 10,
            "z": 1,
            "elements": [
                "integratedterminals:menril_glass@0"
            ]
        },
        {
            "x": 14,
            "y": 10,
            "z": 0,
            "elements": [
                "integratedterminals:menril_glass@0"
            ]
        },
        {
            "x": -13,
            "y": 6,
            "z": 18,
            "elements": [
                "extendedcrafting:storage@1"
            ]
        },
        {
            "x": 14,
            "y": 10,
            "z": -1,
            "elements": [
                "integratedterminals:menril_glass@0"
            ]
        },
        {
            "x": 20,
            "y": 20,
            "z": 6,
            "elements": [
                "contenttweaker:sky_block@0"
            ]
        },
        {
            "x": -13,
            "y": 6,
            "z": 19,
            "elements": [
                "extendedcrafting:storage@1"
            ]
        },
        {
            "x": -13,
            "y": 6,
            "z": 17,
            "elements": [
                "extendedcrafting:storage@1"
            ]
        },
        {
            "x": 20,
            "y": 20,
            "z": 2,
            "elements": [
                "tp:hardened_stone_bricks@0"
            ]
        },
        {
            "x": 14,
            "y": 10,
            "z": 3,
            "elements": [
                "integratedterminals:menril_glass@0"
            ]
        },
        {
            "x": -13,
            "y": 6,
            "z": -8,
            "elements": [
                "extendedcrafting:storage@1"
            ]
        },
        {
            "x": 14,
            "y": 10,
            "z": -2,
            "elements": [
                "integratedterminals:menril_glass@0"
            ]
        },
        {
            "x": -13,
            "y": 6,
            "z": -7,
            "elements": [
                "extendedcrafting:storage@1"
            ]
        },
        {
            "x": 14,
            "y": 10,
            "z": -3,
            "elements": [
                "integratedterminals:menril_glass@0"
            ]
        },
        {
            "x": -1,
            "y": 18,
            "z": -19,
            "elements": [
                "prodigytech:zorrasteel_block@0"
            ]
        },
        {
            "x": -13,
            "y": 6,
            "z": -9,
            "elements": [
                "extendedcrafting:storage@1"
            ]
        },
        {
            "x": 6,
            "y": 2,
            "z": 9,
            "elements": [
                "astralsorcery:blockmarble@6"
            ]
        },
        {
            "x": 6,
            "y": 2,
            "z": 8,
            "elements": [
                "astralsorcery:blockmarble@6"
            ]
        },
        {
            "x": 6,
            "y": 2,
            "z": 7,
            "elements": [
                "astralsorcery:blockmarble@6"
            ]
        },
        {
            "x": -2,
            "y": 15,
            "z": 10,
            "elements": [
                "prodigytech:ferramic_block@0"
            ]
        },
        {
            "x": -2,
            "y": 15,
            "z": 15,
            "elements": [
                "deepmoblearning:infused_ingot_block@0"
            ]
        },
        {
            "x": -2,
            "y": 15,
            "z": 14,
            "elements": [
                "integratedterminals:menril_glass@0"
            ]
        },
        {
            "x": 6,
            "y": 2,
            "z": 19,
            "elements": [
                "astralsorcery:blockmarble@6"
            ]
        },
        {
            "x": -2,
            "y": 15,
            "z": 9,
            "elements": [
                "astraladditions:block_starmetal@0"
            ]
        },
        {
            "x": 6,
            "y": 2,
            "z": 18,
            "elements": [
                "astralsorcery:blockmarble@6"
            ]
        },
        {
            "x": -2,
            "y": 15,
            "z": 8,
            "elements": [
                "astraladditions:block_starmetal@0"
            ]
        },
        {
            "x": 6,
            "y": 2,
            "z": 17,
            "elements": [
                "astralsorcery:blockmarble@6"
            ]
        },
        {
            "x": -2,
            "y": 15,
            "z": 7,
            "elements": [
                "astraladditions:block_starmetal@0"
            ]
        },
        {
            "x": -2,
            "y": 15,
            "z": 6,
            "elements": [
                "prodigytech:ferramic_block@0"
            ]
        },
        {
            "x": 6,
            "y": 2,
            "z": -18,
            "elements": [
                "astralsorcery:blockmarble@6"
            ]
        },
        {
            "x": 6,
            "y": 2,
            "z": -19,
            "elements": [
                "astralsorcery:blockmarble@6"
            ]
        },
        {
            "x": 12,
            "y": 12,
            "z": -8,
            "elements": [
                "integratedterminals:menril_glass@0"
            ]
        },
        {
            "x": 12,
            "y": 12,
            "z": -7,
            "elements": [
                "integratedterminals:menril_glass@0"
            ]
        },
        {
            "x": -4,
            "y": 17,
            "z": -14,
            "elements": [
                "deepmoblearning:infused_ingot_block@0"
            ]
        },
        {
            "x": -4,
            "y": 17,
            "z": -13,
            "elements": [
                "integratedterminals:menril_glass@0"
            ]
        },
        {
            "x": 6,
            "y": 2,
            "z": -7,
            "elements": [
                "astralsorcery:blockmarble@6"
            ]
        },
        {
            "x": 6,
            "y": 2,
            "z": -8,
            "elements": [
                "astralsorcery:blockmarble@6"
            ]
        },
        {
            "x": 6,
            "y": 2,
            "z": -9,
            "elements": [
                "astralsorcery:blockmarble@6"
            ]
        },
        {
            "x": 12,
            "y": 12,
            "z": 7,
            "elements": [
                "integratedterminals:menril_glass@0"
            ]
        },
        {
            "x": 12,
            "y": 12,
            "z": 8,
            "elements": [
                "integratedterminals:menril_glass@0"
            ]
        },
        {
            "x": 6,
            "y": 2,
            "z": -17,
            "elements": [
                "astralsorcery:blockmarble@6"
            ]
        },
        {
            "x": -7,
            "y": 8,
            "z": 16,
            "elements": [
                "astralsorcery:blockmarble@6"
            ]
        },
        {
            "x": -7,
            "y": 8,
            "z": 17,
            "elements": [
                "astraladditions:block_starmetal@0"
            ]
        },
        {
            "x": -7,
            "y": 8,
            "z": 18,
            "elements": [
                "astraladditions:block_starmetal@0"
            ]
        },
        {
            "x": -7,
            "y": 8,
            "z": 19,
            "elements": [
                "astraladditions:block_starmetal@0"
            ]
        },
        {
            "x": -7,
            "y": 8,
            "z": 20,
            "elements": [
                "astralsorcery:blockmarble@6"
            ]
        },
        {
            "x": 17,
            "y": 19,
            "z": -10,
            "elements": [
                "astraladditions:block_starmetal@0"
            ]
        },
        {
            "x": -8,
            "y": 13,
            "z": 18,
            "elements": [
                "chisel:futura@4"
            ]
        },
        {
            "x": -2,
            "y": 15,
            "z": -6,
            "elements": [
                "prodigytech:ferramic_block@0"
            ]
        },
        {
            "x": -8,
            "y": 13,
            "z": 19,
            "elements": [
                "minecraft:purpur_block@0"
            ]
        },
        {
            "x": 17,
            "y": 19,
            "z": -6,
            "elements": [
                "astraladditions:block_starmetal@0"
            ]
        },
        {
            "x": 17,
            "y": 19,
            "z": -7,
            "elements": [
                "extendedcrafting:storage@3"
            ]
        },
        {
            "x": -2,
            "y": 15,
            "z": 0,
            "elements": [
                "tconstruct:clear_glass@0"
            ]
        },
        {
            "x": 17,
            "y": 19,
            "z": -8,
            "elements": [
                "extendedcrafting:storage@3"
            ]
        },
        {
            "x": 17,
            "y": 19,
            "z": -9,
            "elements": [
                "extendedcrafting:storage@3"
            ]
        },
        {
            "x": 17,
            "y": 19,
            "z": -2,
            "elements": [
                "astraladditions:block_starmetal@0"
            ]
        },
        {
            "x": -8,
            "y": 13,
            "z": 12,
            "elements": [
                "integratedterminals:menril_glass@0"
            ]
        },
        {
            "x": -8,
            "y": 13,
            "z": 13,
            "elements": [
                "deepmoblearning:infused_ingot_block@0"
            ]
        },
        {
            "x": -2,
            "y": 15,
            "z": -14,
            "elements": [
                "integratedterminals:menril_glass@0"
            ]
        },
        {
            "x": -2,
            "y": 15,
            "z": -7,
            "elements": [
                "astraladditions:block_starmetal@0"
            ]
        },
        {
            "x": 17,
            "y": 19,
            "z": 2,
            "elements": [
                "astraladditions:block_starmetal@0"
            ]
        },
        {
            "x": -2,
            "y": 15,
            "z": -8,
            "elements": [
                "astraladditions:block_starmetal@0"
            ]
        },
        {
            "x": 17,
            "y": 19,
            "z": 1,
            "elements": [
                "naturesaura:infused_iron_block@0"
            ]
        },
        {
            "x": -8,
            "y": 13,
            "z": 17,
            "elements": [
                "minecraft:purpur_block@0"
            ]
        },
        {
            "x": -2,
            "y": 15,
            "z": -9,
            "elements": [
                "astraladditions:block_starmetal@0"
            ]
        },
        {
            "x": 17,
            "y": 19,
            "z": 0,
            "elements": [
                "naturesaura:infused_iron_block@0"
            ]
        },
        {
            "x": -2,
            "y": 15,
            "z": -10,
            "elements": [
                "prodigytech:ferramic_block@0"
            ]
        },
        {
            "x": 17,
            "y": 19,
            "z": -1,
            "elements": [
                "naturesaura:infused_iron_block@0"
            ]
        },
        {
            "x": 17,
            "y": 11,
            "z": 17,
            "elements": [
                "tp:netherstar_block@0"
            ]
        },
        {
            "x": 17,
            "y": 11,
            "z": 18,
            "elements": [
                "tp:netherstar_block@0"
            ]
        },
        {
            "x": -2,
            "y": 15,
            "z": -15,
            "elements": [
                "deepmoblearning:infused_ingot_block@0"
            ]
        },
        {
            "x": 17,
            "y": 11,
            "z": 19,
            "elements": [
                "tp:netherstar_block@0"
            ]
        },
        {
            "x": 18,
            "y": 14,
            "z": -7,
            "elements": [
                "minecraft:purpur_block@0"
            ]
        },
        {
            "x": 18,
            "y": 14,
            "z": -9,
            "elements": [
                "minecraft:purpur_block@0"
            ]
        },
        {
            "x": 18,
            "y": 14,
            "z": -8,
            "elements": [
                "chisel:futura@4"
            ]
        },
        {
            "x": -7,
            "y": 16,
            "z": -12,
            "elements": [
                "integratedterminals:menril_glass@0"
            ]
        },
        {
            "x": -7,
            "y": 16,
            "z": -13,
            "elements": [
                "deepmoblearning:infused_ingot_block@0"
            ]
        },
        {
            "x": -7,
            "y": 16,
            "z": -18,
            "elements": [
                "minecraft:purpur_block@0"
            ]
        },
        {
            "x": 17,
            "y": 19,
            "z": 6,
            "elements": [
                "astraladditions:block_starmetal@0"
            ]
        },
        {
            "x": 17,
            "y": 19,
            "z": 10,
            "elements": [
                "astraladditions:block_starmetal@0"
            ]
        },
        {
            "x": 18,
            "y": 14,
            "z": -18,
            "elements": [
                "chisel:futura@4"
            ]
        },
        {
            "x": 17,
            "y": 19,
            "z": 9,
            "elements": [
                "extendedcrafting:storage@3"
            ]
        },
        {
            "x": -7,
            "y": 8,
            "z": -20,
            "elements": [
                "astralsorcery:blockmarble@6"
            ]
        },
        {
            "x": 17,
            "y": 19,
            "z": 8,
            "elements": [
                "extendedcrafting:storage@3"
            ]
        },
        {
            "x": -3,
            "y": 12,
            "z": 14,
            "elements": [
                "integratedterminals:menril_glass@0"
            ]
        },
        {
            "x": -7,
            "y": 8,
            "z": -19,
            "elements": [
                "astraladditions:block_starmetal@0"
            ]
        },
        {
            "x": 17,
            "y": 19,
            "z": 7,
            "elements": [
                "extendedcrafting:storage@3"
            ]
        },
        {
            "x": -7,
            "y": 16,
            "z": 2,
            "elements": [
                "tp:hardened_stone_bricks@0"
            ]
        },
        {
            "x": -7,
            "y": 16,
            "z": -2,
            "elements": [
                "tp:hardened_stone_bricks@0"
            ]
        },
        {
            "x": -7,
            "y": 8,
            "z": -10,
            "elements": [
                "astralsorcery:blockmarble@6"
            ]
        },
        {
            "x": -7,
            "y": 8,
            "z": -9,
            "elements": [
                "astraladditions:block_starmetal@0"
            ]
        },
        {
            "x": -7,
            "y": 8,
            "z": -8,
            "elements": [
                "astraladditions:block_starmetal@0"
            ]
        },
        {
            "x": -7,
            "y": 8,
            "z": -7,
            "elements": [
                "astraladditions:block_starmetal@0"
            ]
        },
        {
            "x": -7,
            "y": 8,
            "z": -6,
            "elements": [
                "astralsorcery:blockmarble@6"
            ]
        },
        {
            "x": -7,
            "y": 8,
            "z": -18,
            "elements": [
                "astraladditions:block_starmetal@0"
            ]
        },
        {
            "x": -7,
            "y": 8,
            "z": -17,
            "elements": [
                "astraladditions:block_starmetal@0"
            ]
        },
        {
            "x": -7,
            "y": 8,
            "z": -16,
            "elements": [
                "astralsorcery:blockmarble@6"
            ]
        },
        {
            "x": -7,
            "y": 8,
            "z": 6,
            "elements": [
                "astralsorcery:blockmarble@6"
            ]
        },
        {
            "x": -7,
            "y": 8,
            "z": 7,
            "elements": [
                "astraladditions:block_starmetal@0"
            ]
        },
        {
            "x": -7,
            "y": 8,
            "z": 8,
            "elements": [
                "astraladditions:block_starmetal@0"
            ]
        },
        {
            "x": -7,
            "y": 8,
            "z": 9,
            "elements": [
                "astraladditions:block_starmetal@0"
            ]
        },
        {
            "x": -7,
            "y": 8,
            "z": 10,
            "elements": [
                "astralsorcery:blockmarble@6"
            ]
        },
        {
            "x": 2,
            "y": -2,
            "z": 0,
           
            "elements": [
                "modularmachinery:blockcasing@4"
            ]
        },
        {
            "x": 2,
            "y": -2,
            "z": -1,
           
            "elements": [
                "modularmachinery:blockcasing@4"
            ]
        },
        {
            "x": 2,
            "y": -2,
            "z": 2,
           
            "elements": [
                "modularmachinery:blockcasing@4"
            ]
        },
        {
            "x": 2,
            "y": -2,
            "z": 1,
           
            "elements": [
                "modularmachinery:blockcasing@4"
            ]
        },
        {
            "x": -6,
            "y": 11,
            "z": 13,
            "elements": [
                "integratedterminals:menril_glass@0"
            ]
        },
        {
            "x": 2,
            "y": -2,
            "z": -8,
           
            "elements": [
                "environmentaltech:structure_panel@0"
            ]
        },
        {
            "x": 2,
            "y": -2,
            "z": -9,
           
            "elements": [
                "modularmachinery:blockcasing@4"
            ]
        },
        {
            "x": 2,
            "y": -2,
            "z": -7,
           
            "elements": [
                "modularmachinery:blockcasing@4"
            ]
        },
        {
            "x": 2,
            "y": -2,
            "z": -2,
           
            "elements": [
                "modularmachinery:blockcasing@4"
            ]
        },
        {
            "x": 2,
            "y": -2,
            "z": -17,
           
            "elements": [
                "modularmachinery:blockcasing@4"
            ]
        },
        {
            "x": 2,
            "y": -2,
            "z": -18,
           
            "elements": [
                "environmentaltech:structure_panel@0"
            ]
        },
        {
            "x": 2,
            "y": -2,
            "z": -19,
           
            "elements": [
                "modularmachinery:blockcasing@4"
            ]
        },
        {
            "x": -9,
            "y": 10,
            "z": 18,
            "elements": [
                "tp:netherstar_block@0"
            ]
        },
        {
            "x": -9,
            "y": 10,
            "z": 19,
            "elements": [
                "tp:netherstar_block@0"
            ]
        },
        {
            "x": -11,
            "y": 12,
            "z": 9,
            "elements": [
                "integratedterminals:menril_glass@0"
            ]
        },
        {
            "x": -9,
            "y": 10,
            "z": 17,
            "elements": [
                "tp:netherstar_block@0"
            ]
        },
        {
            "x": 18,
            "y": 14,
            "z": 9,
            "elements": [
                "minecraft:purpur_block@0"
            ]
        },
        {
            "x": -3,
            "y": 12,
            "z": -14,
            "elements": [
                "integratedterminals:menril_glass@0"
            ]
        },
        {
            "x": 18,
            "y": 14,
            "z": 7,
            "elements": [
                "minecraft:purpur_block@0"
            ]
        },
        {
            "x": 2,
            "y": -2,
            "z": 18,
           
            "elements": [
                "environmentaltech:structure_panel@0"
            ]
        },
        {
            "x": 18,
            "y": 14,
            "z": 8,
            "elements": [
                "chisel:futura@4"
            ]
        },
        {
            "x": 2,
            "y": -2,
            "z": 17,
           
            "elements": [
                "modularmachinery:blockcasing@4"
            ]
        },
        {
            "x": 2,
            "y": -2,
            "z": 19,
           
            "elements": [
                "modularmachinery:blockcasing@4"
            ]
        },
        {
            "x": -11,
            "y": 12,
            "z": -9,
            "elements": [
                "integratedterminals:menril_glass@0"
            ]
        },
        {
            "x": 2,
            "y": -2,
            "z": 8,
           
            "elements": [
                "environmentaltech:structure_panel@0"
            ]
        },
        {
            "x": 2,
            "y": -2,
            "z": 7,
           
            "elements": [
                "modularmachinery:blockcasing@4"
            ]
        },
        {
            "x": 18,
            "y": 14,
            "z": 18,
            "elements": [
                "chisel:futura@4"
            ]
        },
        {
            "x": 2,
            "y": -2,
            "z": 9,
           
            "elements": [
                "modularmachinery:blockcasing@4"
            ]
        },
        {
            "x": -8,
            "y": 13,
            "z": -12,
            "elements": [
                "integratedterminals:menril_glass@0"
            ]
        },
        {
            "x": -8,
            "y": 13,
            "z": -13,
            "elements": [
                "deepmoblearning:infused_ingot_block@0"
            ]
        },
        {
            "x": -8,
            "y": 13,
            "z": -8,
            "elements": [
                "chisel:futura@4"
            ]
        },
        {
            "x": -8,
            "y": 13,
            "z": -19,
            "elements": [
                "minecraft:purpur_block@0"
            ]
        },
        {
            "x": -8,
            "y": 13,
            "z": -18,
            "elements": [
                "chisel:futura@4"
            ]
        },
        {
            "x": -8,
            "y": 13,
            "z": -17,
            "elements": [
                "minecraft:purpur_block@0"
            ]
        },
        {
            "x": 19,
            "y": 17,
            "z": 2,
            "elements": [
                "tp:hardened_stone_bricks@0"
            ]
        },
        {
            "x": -8,
            "y": 13,
            "z": 5,
            "elements": [
                "astraladditions:block_starmetal@0"
            ]
        },
        {
            "x": -8,
            "y": 13,
            "z": 2,
            "elements": [
                "astraladditions:block_starmetal@0"
            ]
        },
        {
            "x": 19,
            "y": 17,
            "z": -2,
            "elements": [
                "tp:hardened_stone_bricks@0"
            ]
        },
        {
            "x": -8,
            "y": 13,
            "z": 8,
            "elements": [
                "chisel:futura@4"
            ]
        },
        {
            "x": 19,
            "y": 17,
            "z": -6,
            "elements": [
                "contenttweaker:sky_block@0"
            ]
        },
        {
            "x": 19,
            "y": 17,
            "z": -8,
            "elements": [
                "minecraft:purpur_block@0"
            ]
        },
        {
            "x": -8,
            "y": 13,
            "z": -5,
            "elements": [
                "astraladditions:block_starmetal@0"
            ]
        },
        {
            "x": 19,
            "y": 17,
            "z": -10,
            "elements": [
                "contenttweaker:sky_block@0"
            ]
        },
        {
            "x": -8,
            "y": 13,
            "z": 0,
            "elements": [
                "naturesaura:infused_iron_block@0"
            ]
        },
        {
            "x": -8,
            "y": 13,
            "z": 1,
            "elements": [
                "naturesaura:infused_iron_block@0"
            ]
        },
        {
            "x": -8,
            "y": 13,
            "z": -2,
            "elements": [
                "astraladditions:block_starmetal@0"
            ]
        },
        {
            "x": -8,
            "y": 13,
            "z": -1,
            "elements": [
                "naturesaura:infused_iron_block@0"
            ]
        },
        {
            "x": -6,
            "y": 11,
            "z": -13,
            "elements": [
                "integratedterminals:menril_glass@0"
            ]
        },
        {
            "x": 20,
            "y": 12,
            "z": 19,
            "elements": [
                "astralsorcery:blockmarble@6"
            ]
        },
        {
            "x": 20,
            "y": 12,
            "z": 18,
            "elements": [
                "astralsorcery:blockmarble@6"
            ]
        },
        {
            "x": 20,
            "y": 12,
            "z": 17,
            "elements": [
                "astralsorcery:blockmarble@6"
            ]
        },
        {
            "x": 20,
            "y": 12,
            "z": 8,
            "elements": [
                "astralsorcery:blockmarble@6"
            ]
        },
        {
            "x": 20,
            "y": 12,
            "z": 7,
            "elements": [
                "astralsorcery:blockmarble@6"
            ]
        },
        {
            "x": 20,
            "y": 12,
            "z": 9,
            "elements": [
                "astralsorcery:blockmarble@6"
            ]
        },
        {
            "x": -10,
            "y": 15,
            "z": -10,
            "elements": [
                "integratedterminals:menril_glass@0"
            ]
        },
        {
            "x": -10,
            "y": 15,
            "z": -9,
            "elements": [
                "extrautils2:ineffableglass@0"
            ]
        },
        {
            "x": 0,
            "y": 0,
            "z": 0,
           
            "elements": [
                "modularmachinery:blockcontroller@2"
            ]
        },
        {
            "x": -10,
            "y": 15,
            "z": -11,
            "elements": [
                "deepmoblearning:infused_ingot_block@0"
            ]
        },
        {
            "x": 9,
            "y": 11,
            "z": 19,
            "elements": [
                "tp:netherstar_block@0"
            ]
        },
        {
            "x": 0,
            "y": 13,
            "z": 9,
            "elements": [
                "prodigytech:zorrasteel_block@0"
            ]
        },
        {
            "x": 0,
            "y": 13,
            "z": 8,
            "elements": [
                "prodigytech:zorrasteel_block@0"
            ]
        },
        {
            "x": 0,
            "y": 13,
            "z": 7,
            "elements": [
                "prodigytech:zorrasteel_block@0"
            ]
        },
        {
            "x": -10,
            "y": 15,
            "z": 2,
            "elements": [
                "tp:hardened_stone_bricks@0"
            ]
        },
        {
            "x": 0,
            "y": 13,
            "z": 3,
            "elements": [
                "tconstruct:clear_glass@0"
            ]
        },
        {
            "x": 0,
            "y": 13,
            "z": 2,
            "elements": [
                "tconstruct:clear_glass@0"
            ]
        },
        {
            "x": -10,
            "y": 15,
            "z": -2,
            "elements": [
                "tp:hardened_stone_bricks@0"
            ]
        },
        {
            "x": 0,
            "y": 13,
            "z": 15,
            "elements": [
                "deepmoblearning:infused_ingot_block@0"
            ]
        },
        {
            "x": 0,
            "y": 13,
            "z": 14,
            "elements": [
                "integratedterminals:menril_glass@0"
            ]
        },
        {
            "x": 0,
            "y": 13,
            "z": -7,
            "elements": [
                "prodigytech:zorrasteel_block@0"
            ]
        },
        {
            "x": 0,
            "y": 13,
            "z": -8,
            "elements": [
                "prodigytech:zorrasteel_block@0"
            ]
        },
        {
            "x": 9,
            "y": 11,
            "z": -7,
            "elements": [
                "tp:netherstar_block@0"
            ]
        },
        {
            "x": 0,
            "y": 13,
            "z": -9,
            "elements": [
                "prodigytech:zorrasteel_block@0"
            ]
        },
        {
            "x": 9,
            "y": 11,
            "z": -8,
            "elements": [
                "tp:netherstar_block@0"
            ]
        },
        {
            "x": -13,
            "y": -2,
            "z": 19,
           
            "elements": [
                "modularmachinery:blockcasing@4"
            ]
        },
        {
            "x": 9,
            "y": 11,
            "z": -9,
            "elements": [
                "tp:netherstar_block@0"
            ]
        },
        {
            "x": -13,
            "y": -2,
            "z": 18,
           
            "elements": [
                "environmentaltech:structure_panel@0"
            ]
        },
        {
            "x": -13,
            "y": -2,
            "z": 17,
           
            "elements": [
                "modularmachinery:blockcasing@4"
            ]
        },
        {
            "x": 9,
            "y": 11,
            "z": -11,
            "elements": [
                "integratedterminals:menril_glass@0"
            ]
        },
        {
            "x": -13,
            "y": -2,
            "z": 15,
            "elements": [
                "tp:netherstar_block@0"
            ]
        },
        {
            "x": 0,
            "y": 13,
            "z": -14,
            "elements": [
                "integratedterminals:menril_glass@0"
            ]
        },
        {
            "x": -13,
            "y": -2,
            "z": 14,
            "elements": [
                "tp:netherstar_block@0"
            ]
        },
        {
            "x": 0,
            "y": 13,
            "z": 1,
            "elements": [
                "tconstruct:clear_glass@0"
            ]
        },
        {
            "x": 0,
            "y": 13,
            "z": 0,
            "elements": [
                "integrateddynamics:block_menril_resin@0"
            ]
        },
        {
            "x": 0,
            "y": 13,
            "z": -1,
            "elements": [
                "tconstruct:clear_glass@0"
            ]
        },
        {
            "x": 0,
            "y": 13,
            "z": -2,
            "elements": [
                "tconstruct:clear_glass@0"
            ]
        },
        {
            "x": 0,
            "y": 13,
            "z": -3,
            "elements": [
                "tconstruct:clear_glass@0"
            ]
        },
        {
            "x": -10,
            "y": 15,
            "z": 10,
            "elements": [
                "integratedterminals:menril_glass@0"
            ]
        },
        {
            "x": -10,
            "y": 15,
            "z": 11,
            "elements": [
                "deepmoblearning:infused_ingot_block@0"
            ]
        },
        {
            "x": 9,
            "y": 11,
            "z": 9,
            "elements": [
                "tp:netherstar_block@0"
            ]
        },
        {
            "x": 9,
            "y": 11,
            "z": 8,
            "elements": [
                "tp:netherstar_block@0"
            ]
        },
        {
            "x": 9,
            "y": 11,
            "z": 7,
            "elements": [
                "tp:netherstar_block@0"
            ]
        },
        {
            "x": -13,
            "y": -2,
            "z": 1,
           
            "elements": [
                "modularmachinery:blockcasing@4"
            ]
        },
        {
            "x": -13,
            "y": -2,
            "z": 0,
           
            "elements": [
                "environmentaltech:structure_panel@0"
            ]
        },
        {
            "x": -13,
            "y": -2,
            "z": -1,
           
            "elements": [
                "modularmachinery:blockcasing@4"
            ]
        },
        {
            "x": 0,
            "y": 13,
            "z": -15,
            "elements": [
                "deepmoblearning:infused_ingot_block@0"
            ]
        },
        {
            "x": -13,
            "y": -2,
            "z": 13,
            "elements": [
                "tp:netherstar_block@0"
            ]
        },
        {
            "x": 9,
            "y": 11,
            "z": 18,
            "elements": [
                "tp:netherstar_block@0"
            ]
        },
        {
            "x": -13,
            "y": -2,
            "z": 12,
            "elements": [
                "tp:netherstar_block@0"
            ]
        },
        {
            "x": 9,
            "y": 11,
            "z": 17,
            "elements": [
                "tp:netherstar_block@0"
            ]
        },
        {
            "x": -13,
            "y": -2,
            "z": 11,
            "elements": [
                "tp:netherstar_block@0"
            ]
        },
        {
            "x": -13,
            "y": -2,
            "z": 9,
           
            "elements": [
                "modularmachinery:blockcasing@4"
            ]
        },
        {
            "x": -13,
            "y": -2,
            "z": 8,
           
            "elements": [
                "environmentaltech:structure_panel@0"
            ]
        },
        {
            "x": -13,
            "y": -2,
            "z": 7,
           
            "elements": [
                "modularmachinery:blockcasing@4"
            ]
        },
        {
            "x": 9,
            "y": 11,
            "z": 11,
            "elements": [
                "integratedterminals:menril_glass@0"
            ]
        },
        {
            "x": -13,
            "y": -2,
            "z": -11,
            "elements": [
                "tp:netherstar_block@0"
            ]
        },
        {
            "x": -13,
            "y": -2,
            "z": -12,
            "elements": [
                "tp:netherstar_block@0"
            ]
        },
        {
            "x": -13,
            "y": -2,
            "z": -13,
            "elements": [
                "tp:netherstar_block@0"
            ]
        },
        {
            "x": -13,
            "y": -2,
            "z": -14,
            "elements": [
                "tp:netherstar_block@0"
            ]
        },
        {
            "x": -13,
            "y": -2,
            "z": -15,
            "elements": [
                "tp:netherstar_block@0"
            ]
        },
        {
            "x": 20,
            "y": 12,
            "z": -17,
            "elements": [
                "astralsorcery:blockmarble@6"
            ]
        },
        {
            "x": -13,
            "y": -2,
            "z": -17,
           
            "elements": [
                "modularmachinery:blockcasing@4"
            ]
        },
        {
            "x": -13,
            "y": -2,
            "z": -18,
           
            "elements": [
                "environmentaltech:structure_panel@0"
            ]
        },
        {
            "x": 20,
            "y": 12,
            "z": -18,
            "elements": [
                "astralsorcery:blockmarble@6"
            ]
        },
        {
            "x": 20,
            "y": 12,
            "z": -19,
            "elements": [
                "astralsorcery:blockmarble@6"
            ]
        },
        {
            "x": -13,
            "y": -2,
            "z": -7,
           
            "elements": [
                "modularmachinery:blockcasing@4"
            ]
        },
        {
            "x": -13,
            "y": -2,
            "z": -8,
           
            "elements": [
                "environmentaltech:structure_panel@0"
            ]
        },
        {
            "x": -13,
            "y": -2,
            "z": -9,
           
            "elements": [
                "modularmachinery:blockcasing@4"
            ]
        },
        {
            "x": -13,
            "y": -2,
            "z": -19,
           
            "elements": [
                "modularmachinery:blockcasing@4"
            ]
        },
        {
            "x": 9,
            "y": 11,
            "z": -17,
            "elements": [
                "tp:netherstar_block@0"
            ]
        },
        {
            "x": 9,
            "y": 11,
            "z": -18,
            "elements": [
                "tp:netherstar_block@0"
            ]
        },
        {
            "x": 20,
            "y": 12,
            "z": -8,
            "elements": [
                "astralsorcery:blockmarble@6"
            ]
        },
        {
            "x": 9,
            "y": 11,
            "z": -19,
            "elements": [
                "tp:netherstar_block@0"
            ]
        },
        {
            "x": 20,
            "y": 12,
            "z": -9,
            "elements": [
                "astralsorcery:blockmarble@6"
            ]
        },
        {
            "x": 20,
            "y": 12,
            "z": -7,
            "elements": [
                "astralsorcery:blockmarble@6"
            ]
        },
        {
            "x": 10,
            "y": -2,
            "z": 1,
           
            "elements": [
                "modularmachinery:blockcasing@4"
            ]
        },
        {
            "x": 10,
            "y": -2,
            "z": -1,
           
            "elements": [
                "modularmachinery:blockcasing@4"
            ]
        },
        {
            "x": 10,
            "y": -2,
            "z": 0,
           
            "elements": [
                "environmentaltech:structure_panel@0"
            ]
        },
        {
            "x": -14,
            "y": 11,
            "z": 2,
            "elements": [
                "integratedterminals:menril_glass@0"
            ]
        },
        {
            "x": -14,
            "y": 11,
            "z": 3,
            "elements": [
                "integratedterminals:menril_glass@0"
            ]
        },
        {
            "x": 10,
            "y": -2,
            "z": 9,
            "elements": [
                "astralsorcery:blockmarble@6"
            ]
        },
        {
            "x": 10,
            "y": -2,
            "z": 7,
            "elements": [
                "astralsorcery:blockmarble@6"
            ]
        },
        {
            "x": 10,
            "y": -2,
            "z": 8,
            "elements": [
                "astralsorcery:blockmarble@6"
            ]
        },
        {
            "x": 10,
            "y": -2,
            "z": 19,
            "elements": [
                "astralsorcery:blockmarble@6"
            ]
        },
        {
            "x": -14,
            "y": 11,
            "z": -3,
            "elements": [
                "integratedterminals:menril_glass@0"
            ]
        },
        {
            "x": -14,
            "y": 11,
            "z": -2,
            "elements": [
                "integratedterminals:menril_glass@0"
            ]
        },
        {
            "x": 10,
            "y": -2,
            "z": 17,
            "elements": [
                "astralsorcery:blockmarble@6"
            ]
        },
        {
            "x": -14,
            "y": 11,
            "z": -1,
            "elements": [
                "integratedterminals:menril_glass@0"
            ]
        },
        {
            "x": 10,
            "y": -2,
            "z": 18,
            "elements": [
                "astralsorcery:blockmarble@6"
            ]
        },
        {
            "x": -14,
            "y": 11,
            "z": 0,
            "elements": [
                "integratedterminals:menril_glass@0"
            ]
        },
        {
            "x": 19,
            "y": 9,
            "z": 17,
            "elements": [
                "tp:netherstar_block@0"
            ]
        },
        {
            "x": -14,
            "y": 11,
            "z": 1,
            "elements": [
                "integratedterminals:menril_glass@0"
            ]
        },
        {
            "x": 19,
            "y": 9,
            "z": 18,
            "elements": [
                "tp:netherstar_block@0"
            ]
        },
        {
            "x": 19,
            "y": 9,
            "z": 19,
            "elements": [
                "tp:netherstar_block@0"
            ]
        },
        {
            "x": -9,
            "y": 18,
            "z": -17,
            "elements": [
                "extendedcrafting:storage@3"
            ]
        },
        {
            "x": -16,
            "y": 18,
            "z": 10,
            "elements": [
                "contenttweaker:sky_block@0"
            ]
        },
        {
            "x": -9,
            "y": 18,
            "z": -18,
            "elements": [
                "extendedcrafting:storage@3"
            ]
        },
        {
            "x": 1,
            "y": 16,
            "z": 14,
            "elements": [
                "integratedterminals:menril_glass@0"
            ]
        },
        {
            "x": 1,
            "y": 16,
            "z": 15,
            "elements": [
                "deepmoblearning:infused_ingot_block@0"
            ]
        },
        {
            "x": -16,
            "y": 18,
            "z": 6,
            "elements": [
                "contenttweaker:sky_block@0"
            ]
        },
        {
            "x": 10,
            "y": -2,
            "z": -19,
            "elements": [
                "astralsorcery:blockmarble@6"
            ]
        },
        {
            "x": 10,
            "y": -2,
            "z": -18,
            "elements": [
                "astralsorcery:blockmarble@6"
            ]
        },
        {
            "x": -16,
            "y": 18,
            "z": 18,
            "elements": [
                "minecraft:purpur_block@0"
            ]
        },
        {
            "x": -9,
            "y": 18,
            "z": -19,
            "elements": [
                "extendedcrafting:storage@3"
            ]
        },
        {
            "x": 1,
            "y": 16,
            "z": 2,
            "elements": [
                "tp:netherstar_block@0"
            ]
        },
        {
            "x": -16,
            "y": 18,
            "z": -6,
            "elements": [
                "contenttweaker:sky_block@0"
            ]
        },
        {
            "x": 1,
            "y": 16,
            "z": -2,
            "elements": [
                "tp:netherstar_block@0"
            ]
        },
        {
            "x": 1,
            "y": 16,
            "z": -1,
            "elements": [
                "tp:netherstar_block@0"
            ]
        },
        {
            "x": 10,
            "y": -2,
            "z": -17,
            "elements": [
                "astralsorcery:blockmarble@6"
            ]
        },
        {
            "x": -16,
            "y": 18,
            "z": -10,
            "elements": [
                "contenttweaker:sky_block@0"
            ]
        },
        {
            "x": 1,
            "y": 16,
            "z": 0,
            "elements": [
                "tp:netherstar_block@0"
            ]
        },
        {
            "x": 1,
            "y": 16,
            "z": 1,
            "elements": [
                "tp:netherstar_block@0"
            ]
        },
        {
            "x": -16,
            "y": 18,
            "z": 2,
            "elements": [
                "tp:hardened_stone_bricks@0"
            ]
        },
        {
            "x": 10,
            "y": -2,
            "z": -7,
            "elements": [
                "astralsorcery:blockmarble@6"
            ]
        },
        {
            "x": 10,
            "y": -2,
            "z": -9,
            "elements": [
                "astralsorcery:blockmarble@6"
            ]
        },
        {
            "x": -16,
            "y": 18,
            "z": -2,
            "elements": [
                "tp:hardened_stone_bricks@0"
            ]
        },
        {
            "x": 10,
            "y": -2,
            "z": -8,
            "elements": [
                "astralsorcery:blockmarble@6"
            ]
        },
        {
            "x": 1,
            "y": 16,
            "z": -14,
            "elements": [
                "integratedterminals:menril_glass@0"
            ]
        },
        {
            "x": -9,
            "y": 18,
            "z": 17,
            "elements": [
                "extendedcrafting:storage@3"
            ]
        },
        {
            "x": 10,
            "y": 14,
            "z": -11,
            "elements": [
                "deepmoblearning:infused_ingot_block@0"
            ]
        },
        {
            "x": 10,
            "y": 14,
            "z": -10,
            "elements": [
                "integratedterminals:menril_glass@0"
            ]
        },
        {
            "x": -9,
            "y": 18,
            "z": 19,
            "elements": [
                "extendedcrafting:storage@3"
            ]
        },
        {
            "x": 1,
            "y": 16,
            "z": -15,
            "elements": [
                "deepmoblearning:infused_ingot_block@0"
            ]
        },
        {
            "x": -9,
            "y": 18,
            "z": 18,
            "elements": [
                "extendedcrafting:storage@3"
            ]
        },
        {
            "x": 10,
            "y": 14,
            "z": -2,
            "elements": [
                "tp:hardened_stone_bricks@0"
            ]
        },
        {
            "x": 10,
            "y": 14,
            "z": 2,
            "elements": [
                "tp:hardened_stone_bricks@0"
            ]
        },
        {
            "x": 10,
            "y": 14,
            "z": 11,
            "elements": [
                "deepmoblearning:infused_ingot_block@0"
            ]
        },
        {
            "x": 10,
            "y": 14,
            "z": 10,
            "elements": [
                "integratedterminals:menril_glass@0"
            ]
        },
        {
            "x": 19,
            "y": 9,
            "z": 7,
            "elements": [
                "tp:netherstar_block@0"
            ]
        },
        {
            "x": 19,
            "y": 9,
            "z": 8,
            "elements": [
                "tp:netherstar_block@0"
            ]
        },
        {
            "x": 19,
            "y": 9,
            "z": 9,
            "elements": [
                "tp:netherstar_block@0"
            ]
        },
        {
            "x": 19,
            "y": 9,
            "z": -19,
            "elements": [
                "tp:netherstar_block@0"
            ]
        },
        {
            "x": 19,
            "y": 9,
            "z": -18,
            "elements": [
                "tp:netherstar_block@0"
            ]
        },
        {
            "x": 19,
            "y": 9,
            "z": -17,
            "elements": [
                "tp:netherstar_block@0"
            ]
        },
        {
            "x": 19,
            "y": 9,
            "z": -9,
            "elements": [
                "tp:netherstar_block@0"
            ]
        },
        {
            "x": 19,
            "y": 9,
            "z": -8,
            "elements": [
                "tp:netherstar_block@0"
            ]
        },
        {
            "x": 19,
            "y": 9,
            "z": -7,
            "elements": [
                "tp:netherstar_block@0"
            ]
        },
        {
            "x": 18,
            "y": 6,
            "z": 18,
            "elements": [
                "chisel:futura@4"
            ]
        },
        {
            "x": 18,
            "y": 6,
            "z": 17,
            "elements": [
                "minecraft:purpur_block@0"
            ]
        },
        {
            "x": 18,
            "y": 6,
            "z": 15,
            "elements": [
                "astraladditions:block_starmetal@0"
            ]
        },
        {
            "x": 18,
            "y": 6,
            "z": 19,
            "elements": [
                "minecraft:purpur_block@0"
            ]
        },
        {
            "x": 2,
            "y": 19,
            "z": 16,
            "elements": [
                "prodigytech:ferramic_block@0"
            ]
        },
        {
            "x": 2,
            "y": 19,
            "z": 17,
            "elements": [
                "astraladditions:block_starmetal@0"
            ]
        },
        {
            "x": 2,
            "y": 19,
            "z": 20,
            "elements": [
                "prodigytech:ferramic_block@0"
            ]
        },
        {
            "x": 2,
            "y": 19,
            "z": 18,
            "elements": [
                "astraladditions:block_starmetal@0"
            ]
        },
        {
            "x": 2,
            "y": 19,
            "z": 19,
            "elements": [
                "astraladditions:block_starmetal@0"
            ]
        },
        {
            "x": 2,
            "y": 19,
            "z": -20,
            "elements": [
                "prodigytech:ferramic_block@0"
            ]
        },
        {
            "x": -11,
            "y": 4,
            "z": 8,
            "elements": [
                "astraladditions:block_starmetal@0"
            ]
        },
        {
            "x": 2,
            "y": 19,
            "z": -19,
            "elements": [
                "astraladditions:block_starmetal@0"
            ]
        },
        {
            "x": -11,
            "y": 4,
            "z": 9,
            "elements": [
                "astraladditions:block_starmetal@0"
            ]
        },
        {
            "x": -11,
            "y": 4,
            "z": 6,
            "elements": [
                "extendedcrafting:storage@0"
            ]
        },
        {
            "x": -11,
            "y": 4,
            "z": 7,
            "elements": [
                "astraladditions:block_starmetal@0"
            ]
        },
        {
            "x": 2,
            "y": 19,
            "z": -16,
            "elements": [
                "prodigytech:ferramic_block@0"
            ]
        },
        {
            "x": 2,
            "y": 19,
            "z": -18,
            "elements": [
                "astraladditions:block_starmetal@0"
            ]
        },
        {
            "x": -11,
            "y": 4,
            "z": 10,
            "elements": [
                "extendedcrafting:storage@0"
            ]
        },
        {
            "x": 2,
            "y": 19,
            "z": -17,
            "elements": [
                "astraladditions:block_starmetal@0"
            ]
        },
        {
            "x": -11,
            "y": 4,
            "z": 16,
            "elements": [
                "extendedcrafting:storage@0"
            ]
        },
        {
            "x": -11,
            "y": 4,
            "z": 17,
            "elements": [
                "astraladditions:block_starmetal@0"
            ]
        },
        {
            "x": 18,
            "y": 6,
            "z": -18,
            "elements": [
                "chisel:futura@4"
            ]
        },
        {
            "x": -11,
            "y": 4,
            "z": 20,
            "elements": [
                "extendedcrafting:storage@0"
            ]
        },
        {
            "x": 18,
            "y": 6,
            "z": -19,
            "elements": [
                "minecraft:purpur_block@0"
            ]
        },
        {
            "x": -16,
            "y": 18,
            "z": -18,
            "elements": [
                "minecraft:purpur_block@0"
            ]
        },
        {
            "x": -11,
            "y": 4,
            "z": 18,
            "elements": [
                "astraladditions:block_starmetal@0"
            ]
        },
        {
            "x": -11,
            "y": 4,
            "z": 19,
            "elements": [
                "astraladditions:block_starmetal@0"
            ]
        },
        {
            "x": -11,
            "y": 4,
            "z": -8,
            "elements": [
                "astraladditions:block_starmetal@0"
            ]
        },
        {
            "x": -11,
            "y": 4,
            "z": -7,
            "elements": [
                "astraladditions:block_starmetal@0"
            ]
        },
        {
            "x": -11,
            "y": 4,
            "z": -10,
            "elements": [
                "extendedcrafting:storage@0"
            ]
        },
        {
            "x": -11,
            "y": 4,
            "z": -9,
            "elements": [
                "astraladditions:block_starmetal@0"
            ]
        },
        {
            "x": -11,
            "y": 4,
            "z": -6,
            "elements": [
                "extendedcrafting:storage@0"
            ]
        },
        {
            "x": 7,
            "y": 5,
            "z": 15,
            "elements": [
                "astraladditions:block_starmetal@0"
            ]
        },
        {
            "x": 7,
            "y": 5,
            "z": 11,
            "elements": [
                "astraladditions:block_starmetal@0"
            ]
        },
        {
            "x": 7,
            "y": 5,
            "z": 12,
            "elements": [
                "extendedcrafting:storage@1"
            ]
        },
        {
            "x": 7,
            "y": 5,
            "z": 13,
            "elements": [
                "extendedcrafting:storage@1"
            ]
        },
        {
            "x": 7,
            "y": 5,
            "z": 14,
            "elements": [
                "extendedcrafting:storage@1"
            ]
        },
        {
            "x": -11,
            "y": 4,
            "z": -20,
            "elements": [
                "extendedcrafting:storage@0"
            ]
        },
        {
            "x": -11,
            "y": 4,
            "z": -19,
            "elements": [
                "astraladditions:block_starmetal@0"
            ]
        },
        {
            "x": -11,
            "y": 4,
            "z": -16,
            "elements": [
                "extendedcrafting:storage@0"
            ]
        },
        {
            "x": 18,
            "y": 6,
            "z": 9,
            "elements": [
                "minecraft:purpur_block@0"
            ]
        },
        {
            "x": -11,
            "y": 4,
            "z": -18,
            "elements": [
                "astraladditions:block_starmetal@0"
            ]
        },
        {
            "x": 18,
            "y": 6,
            "z": 8,
            "elements": [
                "chisel:futura@4"
            ]
        },
        {
            "x": -11,
            "y": 4,
            "z": -17,
            "elements": [
                "astraladditions:block_starmetal@0"
            ]
        },
        {
            "x": 18,
            "y": 6,
            "z": 7,
            "elements": [
                "minecraft:purpur_block@0"
            ]
        },
        {
            "x": 18,
            "y": 6,
            "z": 14,
            "elements": [
                "extendedcrafting:storage@1"
            ]
        },
        {
            "x": 18,
            "y": 6,
            "z": 13,
            "elements": [
                "extendedcrafting:storage@1"
            ]
        },
        {
            "x": 18,
            "y": 6,
            "z": 12,
            "elements": [
                "extendedcrafting:storage@1"
            ]
        },
        {
            "x": 18,
            "y": 6,
            "z": 11,
            "elements": [
                "astraladditions:block_starmetal@0"
            ]
        },
        {
            "x": 18,
            "y": 6,
            "z": -14,
            "elements": [
                "extendedcrafting:storage@1"
            ]
        },
        {
            "x": 18,
            "y": 6,
            "z": -15,
            "elements": [
                "astraladditions:block_starmetal@0"
            ]
        },
        {
            "x": 18,
            "y": 6,
            "z": -17,
            "elements": [
                "minecraft:purpur_block@0"
            ]
        },
        {
            "x": 7,
            "y": 5,
            "z": -13,
            "elements": [
                "extendedcrafting:storage@1"
            ]
        },
        {
            "x": 7,
            "y": 5,
            "z": -12,
            "elements": [
                "extendedcrafting:storage@1"
            ]
        },
        {
            "x": 18,
            "y": 6,
            "z": -11,
            "elements": [
                "astraladditions:block_starmetal@0"
            ]
        },
        {
            "x": 18,
            "y": 6,
            "z": -12,
            "elements": [
                "extendedcrafting:storage@1"
            ]
        },
        {
            "x": 7,
            "y": 5,
            "z": -11,
            "elements": [
                "astraladditions:block_starmetal@0"
            ]
        },
        {
            "x": 18,
            "y": 6,
            "z": -13,
            "elements": [
                "extendedcrafting:storage@1"
            ]
        },
        {
            "x": 18,
            "y": 6,
            "z": -7,
            "elements": [
                "minecraft:purpur_block@0"
            ]
        },
        {
            "x": 7,
            "y": 5,
            "z": -15,
            "elements": [
                "astraladditions:block_starmetal@0"
            ]
        },
        {
            "x": 18,
            "y": 6,
            "z": -8,
            "elements": [
                "chisel:futura@4"
            ]
        },
        {
            "x": 7,
            "y": 5,
            "z": -14,
            "elements": [
                "extendedcrafting:storage@1"
            ]
        },
        {
            "x": 18,
            "y": 6,
            "z": -9,
            "elements": [
                "minecraft:purpur_block@0"
            ]
        },
        {
            "x": 12,
            "y": 4,
            "z": -8,
            "elements": [
                "extendedcrafting:storage@1"
            ]
        },
        {
            "x": 12,
            "y": 4,
            "z": -9,
            "elements": [
                "extendedcrafting:storage@1"
            ]
        },
        {
            "x": 12,
            "y": 4,
            "z": -7,
            "elements": [
                "extendedcrafting:storage@1"
            ]
        },
        {
            "x": -16,
            "y": 5,
            "z": 18,
            "elements": [
                "chisel:futura@4"
            ]
        },
        {
            "x": -7,
            "y": 0,
            "z": -9,
            "elements": [
                "tp:netherstar_block@0"
            ]
        },
        {
            "x": -16,
            "y": 5,
            "z": 15,
            "elements": [
                "extendedcrafting:storage@0"
            ]
        },
        {
            "x": -7,
            "y": 0,
            "z": -7,
            "elements": [
                "tp:netherstar_block@0"
            ]
        },
        {
            "x": -7,
            "y": 0,
            "z": -8,
            "elements": [
                "tp:netherstar_block@0"
            ]
        },
        {
            "x": -16,
            "y": 5,
            "z": 11,
            "elements": [
                "extendedcrafting:storage@0"
            ]
        },
        {
            "x": 12,
            "y": 4,
            "z": 8,
            "elements": [
                "extendedcrafting:storage@1"
            ]
        },
        {
            "x": 7,
            "y": 18,
            "z": -19,
            "elements": [
                "extendedcrafting:storage@3"
            ]
        },
        {
            "x": 12,
            "y": 4,
            "z": 7,
            "elements": [
                "extendedcrafting:storage@1"
            ]
        },
        {
            "x": -7,
            "y": 0,
            "z": 17,
            "elements": [
                "tp:netherstar_block@0"
            ]
        },
        {
            "x": -16,
            "y": 5,
            "z": 8,
            "elements": [
                "chisel:futura@4"
            ]
        },
        {
            "x": 12,
            "y": 4,
            "z": 9,
            "elements": [
                "extendedcrafting:storage@1"
            ]
        },
        {
            "x": -7,
            "y": 0,
            "z": 19,
            "elements": [
                "tp:netherstar_block@0"
            ]
        },
        {
            "x": -7,
            "y": 0,
            "z": 18,
            "elements": [
                "tp:netherstar_block@0"
            ]
        },
        {
            "x": -7,
            "y": 0,
            "z": 7,
            "elements": [
                "tp:netherstar_block@0"
            ]
        },
        {
            "x": -7,
            "y": 0,
            "z": 9,
            "elements": [
                "tp:netherstar_block@0"
            ]
        },
        {
            "x": 12,
            "y": 4,
            "z": 18,
            "elements": [
                "extendedcrafting:storage@1"
            ]
        },
        {
            "x": -7,
            "y": 0,
            "z": 8,
            "elements": [
                "tp:netherstar_block@0"
            ]
        },
        {
            "x": 12,
            "y": 4,
            "z": 17,
            "elements": [
                "extendedcrafting:storage@1"
            ]
        },
        {
            "x": 12,
            "y": 4,
            "z": 19,
            "elements": [
                "extendedcrafting:storage@1"
            ]
        },
        {
            "x": 7,
            "y": 18,
            "z": -18,
            "elements": [
                "extendedcrafting:storage@3"
            ]
        },
        {
            "x": 7,
            "y": 18,
            "z": -17,
            "elements": [
                "extendedcrafting:storage@3"
            ]
        },
        {
            "x": -16,
            "y": 5,
            "z": -8,
            "elements": [
                "chisel:futura@4"
            ]
        },
        {
            "x": -16,
            "y": 5,
            "z": -11,
            "elements": [
                "extendedcrafting:storage@0"
            ]
        },
        {
            "x": -18,
            "y": 12,
            "z": 18,
            "elements": [
                "astraladditions:block_starmetal@0"
            ]
        },
        {
            "x": -16,
            "y": 5,
            "z": -18,
            "elements": [
                "chisel:futura@4"
            ]
        },
        {
            "x": -18,
            "y": 12,
            "z": 17,
            "elements": [
                "astraladditions:block_starmetal@0"
            ]
        },
        {
            "x": -16,
            "y": 5,
            "z": -15,
            "elements": [
                "extendedcrafting:storage@0"
            ]
        },
        {
            "x": -18,
            "y": 12,
            "z": 20,
            "elements": [
                "astralsorcery:blockmarble@6"
            ]
        },
        {
            "x": -18,
            "y": 12,
            "z": 19,
            "elements": [
                "astraladditions:block_starmetal@0"
            ]
        },
        {
            "x": -18,
            "y": 12,
            "z": 16,
            "elements": [
                "astralsorcery:blockmarble@6"
            ]
        },
        {
            "x": -7,
            "y": 0,
            "z": -17,
            "elements": [
                "tp:netherstar_block@0"
            ]
        },
        {
            "x": -18,
            "y": 12,
            "z": 10,
            "elements": [
                "astralsorcery:blockmarble@6"
            ]
        },
        {
            "x": -7,
            "y": 0,
            "z": -18,
            "elements": [
                "tp:netherstar_block@0"
            ]
        },
        {
            "x": -18,
            "y": 12,
            "z": 9,
            "elements": [
                "astraladditions:block_starmetal@0"
            ]
        },
        {
            "x": -18,
            "y": 12,
            "z": 6,
            "elements": [
                "astralsorcery:blockmarble@6"
            ]
        },
        {
            "x": 12,
            "y": 4,
            "z": -18,
            "elements": [
                "extendedcrafting:storage@1"
            ]
        },
        {
            "x": -18,
            "y": 12,
            "z": 8,
            "elements": [
                "astraladditions:block_starmetal@0"
            ]
        },
        {
            "x": 12,
            "y": 4,
            "z": -19,
            "elements": [
                "extendedcrafting:storage@1"
            ]
        },
        {
            "x": -18,
            "y": 12,
            "z": 7,
            "elements": [
                "astraladditions:block_starmetal@0"
            ]
        },
        {
            "x": 12,
            "y": 4,
            "z": -17,
            "elements": [
                "extendedcrafting:storage@1"
            ]
        },
        {
            "x": -7,
            "y": 0,
            "z": -19,
            "elements": [
                "tp:netherstar_block@0"
            ]
        },
        {
            "x": 8,
            "y": 8,
            "z": 6,
            "elements": [
                "astralsorcery:blockmarble@6"
            ]
        },
        {
            "x": 17,
            "y": 3,
            "z": -15,
            "elements": [
                "extendedcrafting:storage@0"
            ]
        },
        {
            "x": 8,
            "y": 8,
            "z": -8,
            "elements": [
                "astraladditions:block_starmetal@0"
            ]
        },
        {
            "x": 8,
            "y": 8,
            "z": -9,
            "elements": [
                "astraladditions:block_starmetal@0"
            ]
        },
        {
            "x": 8,
            "y": 8,
            "z": -6,
            "elements": [
                "astralsorcery:blockmarble@6"
            ]
        },
        {
            "x": 8,
            "y": 8,
            "z": -7,
            "elements": [
                "astraladditions:block_starmetal@0"
            ]
        },
        {
            "x": 17,
            "y": 3,
            "z": -18,
            "elements": [
                "minecraft:purpur_pillar@0"
            ]
        },
        {
            "x": -17,
            "y": 2,
            "z": -20,
            "elements": [
                "astralsorcery:blockmarble@6"
            ]
        },
        {
            "x": -17,
            "y": 2,
            "z": -19,
            "elements": [
                "astraladditions:block_starmetal@0"
            ]
        },
        {
            "x": -17,
            "y": 2,
            "z": -18,
            "elements": [
                "astraladditions:block_starmetal@0"
            ]
        },
        {
            "x": 8,
            "y": 8,
            "z": 16,
            "elements": [
                "astralsorcery:blockmarble@6"
            ]
        },
        {
            "x": -17,
            "y": 2,
            "z": -17,
            "elements": [
                "astraladditions:block_starmetal@0"
            ]
        },
        {
            "x": -17,
            "y": 2,
            "z": -16,
            "elements": [
                "astralsorcery:blockmarble@6"
            ]
        },
        {
            "x": 8,
            "y": 8,
            "z": 18,
            "elements": [
                "astraladditions:block_starmetal@0"
            ]
        },
        {
            "x": 8,
            "y": 8,
            "z": 17,
            "elements": [
                "astraladditions:block_starmetal@0"
            ]
        },
        {
            "x": 8,
            "y": 8,
            "z": 20,
            "elements": [
                "astralsorcery:blockmarble@6"
            ]
        },
        {
            "x": 8,
            "y": 8,
            "z": 19,
            "elements": [
                "astraladditions:block_starmetal@0"
            ]
        },
        {
            "x": -17,
            "y": 2,
            "z": -10,
            "elements": [
                "astralsorcery:blockmarble@6"
            ]
        },
        {
            "x": 8,
            "y": 8,
            "z": 8,
            "elements": [
                "astraladditions:block_starmetal@0"
            ]
        },
        {
            "x": -17,
            "y": 2,
            "z": -9,
            "elements": [
                "astraladditions:block_starmetal@0"
            ]
        },
        {
            "x": 8,
            "y": 8,
            "z": 7,
            "elements": [
                "astraladditions:block_starmetal@0"
            ]
        },
        {
            "x": -17,
            "y": 2,
            "z": -8,
            "elements": [
                "astraladditions:block_starmetal@0"
            ]
        },
        {
            "x": 8,
            "y": 8,
            "z": 10,
            "elements": [
                "astralsorcery:blockmarble@6"
            ]
        },
        {
            "x": -17,
            "y": 2,
            "z": -7,
            "elements": [
                "astraladditions:block_starmetal@0"
            ]
        },
        {
            "x": 8,
            "y": 8,
            "z": 9,
            "elements": [
                "astraladditions:block_starmetal@0"
            ]
        },
        {
            "x": -17,
            "y": 2,
            "z": -6,
            "elements": [
                "astralsorcery:blockmarble@6"
            ]
        },
        {
            "x": 17,
            "y": 3,
            "z": 8,
            "elements": [
                "minecraft:purpur_pillar@0"
            ]
        },
        {
            "x": -17,
            "y": 2,
            "z": 6,
            "elements": [
                "astralsorcery:blockmarble@6"
            ]
        },
        {
            "x": -17,
            "y": 2,
            "z": 7,
            "elements": [
                "astraladditions:block_starmetal@0"
            ]
        },
        {
            "x": 17,
            "y": 3,
            "z": 18,
            "elements": [
                "minecraft:purpur_pillar@0"
            ]
        },
        {
            "x": -17,
            "y": 2,
            "z": 8,
            "elements": [
                "astraladditions:block_starmetal@0"
            ]
        },
        {
            "x": 17,
            "y": 3,
            "z": 15,
            "elements": [
                "extendedcrafting:storage@0"
            ]
        },
        {
            "x": -17,
            "y": 2,
            "z": 9,
            "elements": [
                "astraladditions:block_starmetal@0"
            ]
        },
        {
            "x": -17,
            "y": 2,
            "z": 10,
            "elements": [
                "astralsorcery:blockmarble@6"
            ]
        },
        {
            "x": 17,
            "y": 3,
            "z": 11,
            "elements": [
                "extendedcrafting:storage@0"
            ]
        },
        {
            "x": 8,
            "y": 8,
            "z": -16,
            "elements": [
                "astralsorcery:blockmarble@6"
            ]
        },
        {
            "x": 8,
            "y": 8,
            "z": -17,
            "elements": [
                "astraladditions:block_starmetal@0"
            ]
        },
        {
            "x": -17,
            "y": 2,
            "z": 16,
            "elements": [
                "astralsorcery:blockmarble@6"
            ]
        },
        {
            "x": 17,
            "y": 3,
            "z": -8,
            "elements": [
                "minecraft:purpur_pillar@0"
            ]
        },
        {
            "x": -17,
            "y": 2,
            "z": 17,
            "elements": [
                "astraladditions:block_starmetal@0"
            ]
        },
        {
            "x": 17,
            "y": 3,
            "z": -11,
            "elements": [
                "extendedcrafting:storage@0"
            ]
        },
        {
            "x": -17,
            "y": 2,
            "z": 18,
            "elements": [
                "astraladditions:block_starmetal@0"
            ]
        },
        {
            "x": -17,
            "y": 2,
            "z": 19,
            "elements": [
                "astraladditions:block_starmetal@0"
            ]
        },
        {
            "x": 8,
            "y": 8,
            "z": -10,
            "elements": [
                "astralsorcery:blockmarble@6"
            ]
        },
        {
            "x": -17,
            "y": 2,
            "z": 20,
            "elements": [
                "astralsorcery:blockmarble@6"
            ]
        },
        {
            "x": 7,
            "y": 18,
            "z": 18,
            "elements": [
                "extendedcrafting:storage@3"
            ]
        },
        {
            "x": 7,
            "y": 18,
            "z": 19,
            "elements": [
                "extendedcrafting:storage@3"
            ]
        },
        {
            "x": 8,
            "y": 8,
            "z": -20,
            "elements": [
                "astralsorcery:blockmarble@6"
            ]
        },
        {
            "x": 7,
            "y": 18,
            "z": 17,
            "elements": [
                "extendedcrafting:storage@3"
            ]
        },
        {
            "x": 8,
            "y": 8,
            "z": -18,
            "elements": [
                "astraladditions:block_starmetal@0"
            ]
        },
        {
            "x": 8,
            "y": 8,
            "z": -19,
            "elements": [
                "astraladditions:block_starmetal@0"
            ]
        },
        {
            "x": -14,
            "y": 16,
            "z": 6,
            "elements": [
                "deepmoblearning:infused_ingot_block@0"
            ]
        },
        {
            "x": -14,
            "y": 16,
            "z": 5,
            "elements": [
                "deepmoblearning:infused_ingot_block@0"
            ]
        },
        {
            "x": -14,
            "y": 16,
            "z": -4,
            "elements": [
                "deepmoblearning:infused_ingot_block@0"
            ]
        },
        {
            "x": -14,
            "y": 16,
            "z": -5,
            "elements": [
                "deepmoblearning:infused_ingot_block@0"
            ]
        },
        {
            "x": -14,
            "y": 16,
            "z": -6,
            "elements": [
                "deepmoblearning:infused_ingot_block@0"
            ]
        },
        {
            "x": -14,
            "y": 16,
            "z": 0,
            "elements": [
                "integratedterminals:menril_glass@0"
            ]
        },
        {
            "x": -14,
            "y": 16,
            "z": -1,
            "elements": [
                "integratedterminals:menril_glass@0"
            ]
        },
        {
            "x": -14,
            "y": 16,
            "z": -2,
            "elements": [
                "integratedterminals:menril_glass@0"
            ]
        },
        {
            "x": -14,
            "y": 16,
            "z": -3,
            "elements": [
                "integratedterminals:menril_glass@0"
            ]
        },
        {
            "x": -14,
            "y": 16,
            "z": 4,
            "elements": [
                "deepmoblearning:infused_ingot_block@0"
            ]
        },
        {
            "x": -14,
            "y": 16,
            "z": 3,
            "elements": [
                "integratedterminals:menril_glass@0"
            ]
        },
        {
            "x": -14,
            "y": 16,
            "z": 2,
            "elements": [
                "integratedterminals:menril_glass@0"
            ]
        },
        {
            "x": -14,
            "y": 16,
            "z": 1,
            "elements": [
                "integratedterminals:menril_glass@0"
            ]
        },
        {
            "x": -18,
            "y": 12,
            "z": -6,
            "elements": [
                "astralsorcery:blockmarble@6"
            ]
        },
        {
            "x": -18,
            "y": 12,
            "z": -7,
            "elements": [
                "astraladditions:block_starmetal@0"
            ]
        },
        {
            "x": -18,
            "y": 12,
            "z": -10,
            "elements": [
                "astralsorcery:blockmarble@6"
            ]
        },
        {
            "x": -18,
            "y": 12,
            "z": -8,
            "elements": [
                "astraladditions:block_starmetal@0"
            ]
        },
        {
            "x": -18,
            "y": 12,
            "z": -9,
            "elements": [
                "astraladditions:block_starmetal@0"
            ]
        },
        {
            "x": -10,
            "y": 20,
            "z": 16,
            "elements": [
                "contenttweaker:sky_block@0"
            ]
        },
        {
            "x": 8,
            "y": 16,
            "z": 17,
            "elements": [
                "minecraft:purpur_block@0"
            ]
        },
        {
            "x": 8,
            "y": 16,
            "z": 18,
            "elements": [
                "chisel:futura@4"
            ]
        },
        {
            "x": -18,
            "y": 12,
            "z": -18,
            "elements": [
                "astraladditions:block_starmetal@0"
            ]
        },
        {
            "x": -10,
            "y": 20,
            "z": 18,
            "elements": [
                "astraladditions:block_starmetal@0"
            ]
        },
        {
            "x": 8,
            "y": 16,
            "z": 19,
            "elements": [
                "minecraft:purpur_block@0"
            ]
        },
        {
            "x": -18,
            "y": 12,
            "z": -19,
            "elements": [
                "astraladditions:block_starmetal@0"
            ]
        },
        {
            "x": -10,
            "y": 20,
            "z": 17,
            "elements": [
                "astraladditions:block_starmetal@0"
            ]
        },
        {
            "x": -18,
            "y": 12,
            "z": -16,
            "elements": [
                "astralsorcery:blockmarble@6"
            ]
        },
        {
            "x": -10,
            "y": 20,
            "z": 20,
            "elements": [
                "contenttweaker:sky_block@0"
            ]
        },
        {
            "x": -18,
            "y": 12,
            "z": -17,
            "elements": [
                "astraladditions:block_starmetal@0"
            ]
        },
        {
            "x": -10,
            "y": 20,
            "z": 19,
            "elements": [
                "astraladditions:block_starmetal@0"
            ]
        },
        {
            "x": -18,
            "y": 12,
            "z": -20,
            "elements": [
                "astralsorcery:blockmarble@6"
            ]
        },
        {
            "x": 2,
            "y": 11,
            "z": -14,
            "elements": [
                "integratedterminals:menril_glass@0"
            ]
        },
        {
            "x": -10,
            "y": 20,
            "z": -18,
            "elements": [
                "astraladditions:block_starmetal@0"
            ]
        },
        {
            "x": -10,
            "y": 20,
            "z": -19,
            "elements": [
                "astraladditions:block_starmetal@0"
            ]
        },
        {
            "x": -10,
            "y": 20,
            "z": -16,
            "elements": [
                "contenttweaker:sky_block@0"
            ]
        },
        {
            "x": -10,
            "y": 20,
            "z": -17,
            "elements": [
                "astraladditions:block_starmetal@0"
            ]
        },
        {
            "x": 2,
            "y": 11,
            "z": 0,
            "elements": [
                "tconstruct:clear_glass@0"
            ]
        },
        {
            "x": 5,
            "y": 15,
            "z": -7,
            "elements": [
                "astraladditions:block_starmetal@0"
            ]
        },
        {
            "x": 5,
            "y": 15,
            "z": -8,
            "elements": [
                "astraladditions:block_starmetal@0"
            ]
        },
        {
            "x": 5,
            "y": 15,
            "z": -9,
            "elements": [
                "astraladditions:block_starmetal@0"
            ]
        },
        {
            "x": 5,
            "y": 15,
            "z": -13,
            "elements": [
                "integratedterminals:menril_glass@0"
            ]
        },
        {
            "x": 5,
            "y": 15,
            "z": 14,
            "elements": [
                "deepmoblearning:infused_ingot_block@0"
            ]
        },
        {
            "x": 5,
            "y": 15,
            "z": 13,
            "elements": [
                "integratedterminals:menril_glass@0"
            ]
        },
        {
            "x": -10,
            "y": 20,
            "z": -20,
            "elements": [
                "contenttweaker:sky_block@0"
            ]
        },
        {
            "x": 8,
            "y": 16,
            "z": -19,
            "elements": [
                "minecraft:purpur_block@0"
            ]
        },
        {
            "x": 8,
            "y": 16,
            "z": -18,
            "elements": [
                "chisel:futura@4"
            ]
        },
        {
            "x": 5,
            "y": 12,
            "z": -13,
            "elements": [
                "integratedterminals:menril_glass@0"
            ]
        },
        {
            "x": 5,
            "y": 15,
            "z": 9,
            "elements": [
                "astraladditions:block_starmetal@0"
            ]
        },
        {
            "x": 5,
            "y": 15,
            "z": 8,
            "elements": [
                "astraladditions:block_starmetal@0"
            ]
        },
        {
            "x": 5,
            "y": 15,
            "z": 7,
            "elements": [
                "astraladditions:block_starmetal@0"
            ]
        },
        {
            "x": 18,
            "y": 1,
            "z": 17,
            "elements": [
                "tp:netherstar_block@0"
            ]
        },
        {
            "x": 18,
            "y": 1,
            "z": 18,
            "elements": [
                "tp:netherstar_block@0"
            ]
        },
        {
            "x": 2,
            "y": 11,
            "z": 14,
            "elements": [
                "integratedterminals:menril_glass@0"
            ]
        },
        {
            "x": 18,
            "y": 1,
            "z": 19,
            "elements": [
                "tp:netherstar_block@0"
            ]
        },
        {
            "x": 18,
            "y": 1,
            "z": 7,
            "elements": [
                "tp:netherstar_block@0"
            ]
        },
        {
            "x": 18,
            "y": 1,
            "z": 8,
            "elements": [
                "tp:netherstar_block@0"
            ]
        },
        {
            "x": 18,
            "y": 1,
            "z": 9,
            "elements": [
                "tp:netherstar_block@0"
            ]
        },
        {
            "x": 8,
            "y": 16,
            "z": -2,
            "elements": [
                "tp:hardened_stone_bricks@0"
            ]
        },
        {
            "x": 8,
            "y": 16,
            "z": -17,
            "elements": [
                "minecraft:purpur_block@0"
            ]
        },
        {
            "x": 8,
            "y": 16,
            "z": -13,
            "elements": [
                "deepmoblearning:infused_ingot_block@0"
            ]
        },
        {
            "x": 8,
            "y": 16,
            "z": -12,
            "elements": [
                "integratedterminals:menril_glass@0"
            ]
        },
        {
            "x": 5,
            "y": 15,
            "z": -14,
            "elements": [
                "deepmoblearning:infused_ingot_block@0"
            ]
        },
        {
            "x": 18,
            "y": 1,
            "z": -9,
            "elements": [
                "tp:netherstar_block@0"
            ]
        },
        {
            "x": 18,
            "y": 1,
            "z": -8,
            "elements": [
                "tp:netherstar_block@0"
            ]
        },
        {
            "x": 18,
            "y": 1,
            "z": -7,
            "elements": [
                "tp:netherstar_block@0"
            ]
        },
        {
            "x": 8,
            "y": 16,
            "z": 12,
            "elements": [
                "integratedterminals:menril_glass@0"
            ]
        },
        {
            "x": 8,
            "y": 16,
            "z": 13,
            "elements": [
                "deepmoblearning:infused_ingot_block@0"
            ]
        },
        {
            "x": 18,
            "y": 1,
            "z": -19,
            "elements": [
                "tp:netherstar_block@0"
            ]
        },
        {
            "x": 18,
            "y": 1,
            "z": -18,
            "elements": [
                "tp:netherstar_block@0"
            ]
        },
        {
            "x": 18,
            "y": 1,
            "z": -17,
            "elements": [
                "tp:netherstar_block@0"
            ]
        },
        {
            "x": 8,
            "y": 16,
            "z": 2,
            "elements": [
                "tp:hardened_stone_bricks@0"
            ]
        },
        {
            "x": -20,
            "y": 6,
            "z": 11,
            "elements": [
                "extendedcrafting:storage@0"
            ]
        },
        {
            "x": -17,
            "y": 10,
            "z": -17,
            "elements": [
                "tp:netherstar_block@0"
            ]
        },
        {
            "x": -17,
            "y": 10,
            "z": -18,
            "elements": [
                "tp:netherstar_block@0"
            ]
        },
        {
            "x": -17,
            "y": 10,
            "z": -19,
            "elements": [
                "tp:netherstar_block@0"
            ]
        },
